Workbook

Sheet Centro Comando
B2: ⬡ CENTRO COMANDO | O2: STORE HOURS ENGINE
B3: Pianificazione turni · copertura · assenze · straordinari — tutto dal vivo
B6: MONTE ORE | G6: RICHIESTE | L6: COPERTURA | Q6: MARGINE
B7: =Personale!$C$41 -> 504 | G7: =OreRichieste!$I$17 -> 553.76609 | L7: =(Personale!$C$41-Personale!$I$41)/OreRichieste!$I$17 -> 0.65731724 | Q7: =Personale!$C$41-Personale!$I$41-OreRichieste!$I$17 -> -189.76609
B11: ▍ MAPPA SETTIMANALE DEI BUCHI
C12: =Copertura!$A$6 -> 0.22916667 | D12: =Copertura!$A$10 -> 0.27083333 | E12: =Copertura!$A$14 -> 0.3125 | F12: =Copertura!$A$18 -> 0.35416667 | G12: =Copertura!$A$22 -> 0.39583333 | H12: =Copertura!$A$26 -> 0.4375 | I12: =Copertura!$A$30 -> 0.47916667 | J12: =Copertura!$A$34 -> 0.52083333 | K12: =Copertura!$A$38 -> 0.5625 | L12: =Copertura!$A$42 -> 0.60416667 | M12: =Copertura!$A$46 -> 0.64583333 | N12: =Copertura!$A$50 -> 0.6875 | O12: =Copertura!$A$54 -> 0.72916667 | P12: =Copertura!$A$58 -> 0.77083333 | Q12: =Copertura!$A$62 -> 0.8125 | R12: =Copertura!$A$66 -> 0.85416667
B13: Lun | C13: =MAX(0,Copertura!$E$6-Copertura!$C$6,Copertura!$E$7-Copertura!$C$7,Copertura!$E$8-Copertura!$C$8,Copertura!$E$9-Copertura!$C$9) -> 0 | D13: =MAX(0,Copertura!$E$10-Copertura!$C$10,Copertura!$E$11-Copertura!$C$11,Copertura!$E$12-Copertura!$C$12,Copertura!$E$13-Copertura!$C$13) -> 0 | E13: =MAX(0,Copertura!$E$14-Copertura!$C$14,Copertura!$E$15-Copertura!$C$15,Copertura!$E$16-Copertura!$C$16,Copertura!$E$17-Copertura!$C$17) -> 0 | F13: =MAX(0,Copertura!$E$18-Copertura!$C$18,Copertura!$E$19-Copertura!$C$19,Copertura!$E$20-Copertura!$C$20,Copertura!$E$21-Copertura!$C$21) -> 0 | G13: =MAX(0,Copertura!$E$22-Copertura!$C$22,Copertura!$E$23-Copertura!$C$23,Copertura!$E$24-Copertura!$C$24,Copertura!$E$25-Copertura!$C$25) -> 0 | H13: =MAX(0,Copertura!$E$26-Copertura!$C$26,Copertura!$E$27-Copertura!$C$27,Copertura!$E$28-Copertura!$C$28,Copertura!$E$29-Copertura!$C$29) -> 0 | I13: =MAX(0,Copertura!$E$30-Copertura!$C$30,Copertura!$E$31-Copertura!$C$31,Copertura!$E$32-Copertura!$C$32,Copertura!$E$33-Copertura!$C$33) -> 1 | J13: =MAX(0,Copertura!$E$34-Copertura!$C$34,Copertura!$E$35-Copertura!$C$35,Copertura!$E$36-Copertura!$C$36,Copertura!$E$37-Copertura!$C$37) -> 0 | K13: =MAX(0,Copertura!$E$38-Copertura!$C$38,Copertura!$E$39-Copertura!$C$39,Copertura!$E$40-Copertura!$C$40,Copertura!$E$41-Copertura!$C$41) -> 0 | L13: =MAX(0,Copertura!$E$42-Copertura!$C$42,Copertura!$E$43-Copertura!$C$43,Copertura!$E$44-Copertura!$C$44,Copertura!$E$45-Copertura!$C$45) -> 0 | M13: =MAX(0,Copertura!$E$46-Copertura!$C$46,Copertura!$E$47-Copertura!$C$47,Copertura!$E$48-Copertura!$C$48,Copertura!$E$49-Copertura!$C$49) -> 0 | N13: =MAX(0,Copertura!$E$50-Copertura!$C$50,Copertura!$E$51-Copertura!$C$51,Copertura!$E$52-Copertura!$C$52,Copertura!$E$53-Copertura!$C$53) -> 0 | O13: =MAX(0,Copertura!$E$54-Copertura!$C$54,Copertura!$E$55-Copertura!$C$55,Copertura!$E$56-Copertura!$C$56,Copertura!$E$57-Copertura!$C$57) -> 0 | P13: =MAX(0,Copertura!$E$58-Copertura!$C$58,Copertura!$E$59-Copertura!$C$59,Copertura!$E$60-Copertura!$C$60,Copertura!$E$61-Copertura!$C$61) -> 0 | Q13: =MAX(0,Copertura!$E$62-Copertura!$C$62,Copertura!$E$63-Copertura!$C$63,Copertura!$E$64-Copertura!$C$64,Copertura!$E$65-Copertura!$C$65) -> 0 | R13: =MAX(0,Copertura!$E$66-Copertura!$C$66,Copertura!$E$67-Copertura!$C$67,Copertura!$E$68-Copertura!$C$68) -> 0
B14: Mar | C14: =MAX(0,Copertura!$I$6-Copertura!$G$6,Copertura!$I$7-Copertura!$G$7,Copertura!$I$8-Copertura!$G$8,Copertura!$I$9-Copertura!$G$9) -> 0 | D14: =MAX(0,Copertura!$I$10-Copertura!$G$10,Copertura!$I$11-Copertura!$G$11,Copertura!$I$12-Copertura!$G$12,Copertura!$I$13-Copertura!$G$13) -> 0 | E14: =MAX(0,Copertura!$I$14-Copertura!$G$14,Copertura!$I$15-Copertura!$G$15,Copertura!$I$16-Copertura!$G$16,Copertura!$I$17-Copertura!$G$17) -> 0 | F14: =MAX(0,Copertura!$I$18-Copertura!$G$18,Copertura!$I$19-Copertura!$G$19,Copertura!$I$20-Copertura!$G$20,Copertura!$I$21-Copertura!$G$21) -> 0 | G14: =MAX(0,Copertura!$I$22-Copertura!$G$22,Copertura!$I$23-Copertura!$G$23,Copertura!$I$24-Copertura!$G$24,Copertura!$I$25-Copertura!$G$25) -> 0 | H14: =MAX(0,Copertura!$I$26-Copertura!$G$26,Copertura!$I$27-Copertura!$G$27,Copertura!$I$28-Copertura!$G$28,Copertura!$I$29-Copertura!$G$29) -> 0 | I14: =MAX(0,Copertura!$I$30-Copertura!$G$30,Copertura!$I$31-Copertura!$G$31,Copertura!$I$32-Copertura!$G$32,Copertura!$I$33-Copertura!$G$33) -> 0 | J14: =MAX(0,Copertura!$I$34-Copertura!$G$34,Copertura!$I$35-Copertura!$G$35,Copertura!$I$36-Copertura!$G$36,Copertura!$I$37-Copertura!$G$37) -> 0 | K14: =MAX(0,Copertura!$I$38-Copertura!$G$38,Copertura!$I$39-Copertura!$G$39,Copertura!$I$40-Copertura!$G$40,Copertura!$I$41-Copertura!$G$41) -> 0 | L14: =MAX(0,Copertura!$I$42-Copertura!$G$42,Copertura!$I$43-Copertura!$G$43,Copertura!$I$44-Copertura!$G$44,Copertura!$I$45-Copertura!$G$45) -> 1 | M14: =MAX(0,Copertura!$I$46-Copertura!$G$46,Copertura!$I$47-Copertura!$G$47,Copertura!$I$48-Copertura!$G$48,Copertura!$I$49-Copertura!$G$49) -> 0 | N14: =MAX(0,Copertura!$I$50-Copertura!$G$50,Copertura!$I$51-Copertura!$G$51,Copertura!$I$52-Copertura!$G$52,Copertura!$I$53-Copertura!$G$53) -> 0 | O14: =MAX(0,Copertura!$I$54-Copertura!$G$54,Copertura!$I$55-Copertura!$G$55,Copertura!$I$56-Copertura!$G$56,Copertura!$I$57-Copertura!$G$57) -> 0 | P14: =MAX(0,Copertura!$I$58-Copertura!$G$58,Copertura!$I$59-Copertura!$G$59,Copertura!$I$60-Copertura!$G$60,Copertura!$I$61-Copertura!$G$61) -> 0 | Q14: =MAX(0,Copertura!$I$62-Copertura!$G$62,Copertura!$I$63-Copertura!$G$63,Copertura!$I$64-Copertura!$G$64,Copertura!$I$65-Copertura!$G$65) -> 0 | R14: =MAX(0,Copertura!$I$66-Copertura!$G$66,Copertura!$I$67-Copertura!$G$67,Copertura!$I$68-Copertura!$G$68) -> 0
B15: Mer | C15: =MAX(0,Copertura!$M$6-Copertura!$K$6,Copertura!$M$7-Copertura!$K$7,Copertura!$M$8-Copertura!$K$8,Copertura!$M$9-Copertura!$K$9) -> 0 | D15: =MAX(0,Copertura!$M$10-Copertura!$K$10,Copertura!$M$11-Copertura!$K$11,Copertura!$M$12-Copertura!$K$12,Copertura!$M$13-Copertura!$K$13) -> 0 | E15: =MAX(0,Copertura!$M$14-Copertura!$K$14,Copertura!$M$15-Copertura!$K$15,Copertura!$M$16-Copertura!$K$16,Copertura!$M$17-Copertura!$K$17) -> 0 | F15: =MAX(0,Copertura!$M$18-Copertura!$K$18,Copertura!$M$19-Copertura!$K$19,Copertura!$M$20-Copertura!$K$20,Copertura!$M$21-Copertura!$K$21) -> 0 | G15: =MAX(0,Copertura!$M$22-Copertura!$K$22,Copertura!$M$23-Copertura!$K$23,Copertura!$M$24-Copertura!$K$24,Copertura!$M$25-Copertura!$K$25) -> 0 | H15: =MAX(0,Copertura!$M$26-Copertura!$K$26,Copertura!$M$27-Copertura!$K$27,Copertura!$M$28-Copertura!$K$28,Copertura!$M$29-Copertura!$K$29) -> 0 | I15: =MAX(0,Copertura!$M$30-Copertura!$K$30,Copertura!$M$31-Copertura!$K$31,Copertura!$M$32-Copertura!$K$32,Copertura!$M$33-Copertura!$K$33) -> 0 | J15: =MAX(0,Copertura!$M$34-Copertura!$K$34,Copertura!$M$35-Copertura!$K$35,Copertura!$M$36-Copertura!$K$36,Copertura!$M$37-Copertura!$K$37) -> 0 | K15: =MAX(0,Copertura!$M$38-Copertura!$K$38,Copertura!$M$39-Copertura!$K$39,Copertura!$M$40-Copertura!$K$40,Copertura!$M$41-Copertura!$K$41) -> 0 | L15: =MAX(0,Copertura!$M$42-Copertura!$K$42,Copertura!$M$43-Copertura!$K$43,Copertura!$M$44-Copertura!$K$44,Copertura!$M$45-Copertura!$K$45) -> 0 | M15: =MAX(0,Copertura!$M$46-Copertura!$K$46,Copertura!$M$47-Copertura!$K$47,Copertura!$M$48-Copertura!$K$48,Copertura!$M$49-Copertura!$K$49) -> 0 | N15: =MAX(0,Copertura!$M$50-Copertura!$K$50,Copertura!$M$51-Copertura!$K$51,Copertura!$M$52-Copertura!$K$52,Copertura!$M$53-Copertura!$K$53) -> 0 | O15: =MAX(0,Copertura!$M$54-Copertura!$K$54,Copertura!$M$55-Copertura!$K$55,Copertura!$M$56-Copertura!$K$56,Copertura!$M$57-Copertura!$K$57) -> 0 | P15: =MAX(0,Copertura!$M$58-Copertura!$K$58,Copertura!$M$59-Copertura!$K$59,Copertura!$M$60-Copertura!$K$60,Copertura!$M$61-Copertura!$K$61) -> 0 | Q15: =MAX(0,Copertura!$M$62-Copertura!$K$62,Copertura!$M$63-Copertura!$K$63,Copertura!$M$64-Copertura!$K$64,Copertura!$M$65-Copertura!$K$65) -> 0 | R15: =MAX(0,Copertura!$M$66-Copertura!$K$66,Copertura!$M$67-Copertura!$K$67,Copertura!$M$68-Copertura!$K$68) -> 0
B16: Gio | C16: =MAX(0,Copertura!$Q$6-Copertura!$O$6,Copertura!$Q$7-Copertura!$O$7,Copertura!$Q$8-Copertura!$O$8,Copertura!$Q$9-Copertura!$O$9) -> 0 | D16: =MAX(0,Copertura!$Q$10-Copertura!$O$10,Copertura!$Q$11-Copertura!$O$11,Copertura!$Q$12-Copertura!$O$12,Copertura!$Q$13-Copertura!$O$13) -> 0 | E16: =MAX(0,Copertura!$Q$14-Copertura!$O$14,Copertura!$Q$15-Copertura!$O$15,Copertura!$Q$16-Copertura!$O$16,Copertura!$Q$17-Copertura!$O$17) -> 0 | F16: =MAX(0,Copertura!$Q$18-Copertura!$O$18,Copertura!$Q$19-Copertura!$O$19,Copertura!$Q$20-Copertura!$O$20,Copertura!$Q$21-Copertura!$O$21) -> 0 | G16: =MAX(0,Copertura!$Q$22-Copertura!$O$22,Copertura!$Q$23-Copertura!$O$23,Copertura!$Q$24-Copertura!$O$24,Copertura!$Q$25-Copertura!$O$25) -> 0 | H16: =MAX(0,Copertura!$Q$26-Copertura!$O$26,Copertura!$Q$27-Copertura!$O$27,Copertura!$Q$28-Copertura!$O$28,Copertura!$Q$29-Copertura!$O$29) -> 0 | I16: =MAX(0,Copertura!$Q$30-Copertura!$O$30,Copertura!$Q$31-Copertura!$O$31,Copertura!$Q$32-Copertura!$O$32,Copertura!$Q$33-Copertura!$O$33) -> 0 | J16: =MAX(0,Copertura!$Q$34-Copertura!$O$34,Copertura!$Q$35-Copertura!$O$35,Copertura!$Q$36-Copertura!$O$36,Copertura!$Q$37-Copertura!$O$37) -> 0 | K16: =MAX(0,Copertura!$Q$38-Copertura!$O$38,Copertura!$Q$39-Copertura!$O$39,Copertura!$Q$40-Copertura!$O$40,Copertura!$Q$41-Copertura!$O$41) -> 0 | L16: =MAX(0,Copertura!$Q$42-Copertura!$O$42,Copertura!$Q$43-Copertura!$O$43,Copertura!$Q$44-Copertura!$O$44,Copertura!$Q$45-Copertura!$O$45) -> 0 | M16: =MAX(0,Copertura!$Q$46-Copertura!$O$46,Copertura!$Q$47-Copertura!$O$47,Copertura!$Q$48-Copertura!$O$48,Copertura!$Q$49-Copertura!$O$49) -> 0 | N16: =MAX(0,Copertura!$Q$50-Copertura!$O$50,Copertura!$Q$51-Copertura!$O$51,Copertura!$Q$52-Copertura!$O$52,Copertura!$Q$53-Copertura!$O$53) -> 0 | O16: =MAX(0,Copertura!$Q$54-Copertura!$O$54,Copertura!$Q$55-Copertura!$O$55,Copertura!$Q$56-Copertura!$O$56,Copertura!$Q$57-Copertura!$O$57) -> 0 | P16: =MAX(0,Copertura!$Q$58-Copertura!$O$58,Copertura!$Q$59-Copertura!$O$59,Copertura!$Q$60-Copertura!$O$60,Copertura!$Q$61-Copertura!$O$61) -> 0 | Q16: =MAX(0,Copertura!$Q$62-Copertura!$O$62,Copertura!$Q$63-Copertura!$O$63,Copertura!$Q$64-Copertura!$O$64,Copertura!$Q$65-Copertura!$O$65) -> 1 | R16: =MAX(0,Copertura!$Q$66-Copertura!$O$66,Copertura!$Q$67-Copertura!$O$67,Copertura!$Q$68-Copertura!$O$68) -> 0
B17: Ven | C17: =MAX(0,Copertura!$U$6-Copertura!$S$6,Copertura!$U$7-Copertura!$S$7,Copertura!$U$8-Copertura!$S$8,Copertura!$U$9-Copertura!$S$9) -> 0 | D17: =MAX(0,Copertura!$U$10-Copertura!$S$10,Copertura!$U$11-Copertura!$S$11,Copertura!$U$12-Copertura!$S$12,Copertura!$U$13-Copertura!$S$13) -> 0 | E17: =MAX(0,Copertura!$U$14-Copertura!$S$14,Copertura!$U$15-Copertura!$S$15,Copertura!$U$16-Copertura!$S$16,Copertura!$U$17-Copertura!$S$17) -> 0 | F17: =MAX(0,Copertura!$U$18-Copertura!$S$18,Copertura!$U$19-Copertura!$S$19,Copertura!$U$20-Copertura!$S$20,Copertura!$U$21-Copertura!$S$21) -> 0 | G17: =MAX(0,Copertura!$U$22-Copertura!$S$22,Copertura!$U$23-Copertura!$S$23,Copertura!$U$24-Copertura!$S$24,Copertura!$U$25-Copertura!$S$25) -> 0 | H17: =MAX(0,Copertura!$U$26-Copertura!$S$26,Copertura!$U$27-Copertura!$S$27,Copertura!$U$28-Copertura!$S$28,Copertura!$U$29-Copertura!$S$29) -> 0 | I17: =MAX(0,Copertura!$U$30-Copertura!$S$30,Copertura!$U$31-Copertura!$S$31,Copertura!$U$32-Copertura!$S$32,Copertura!$U$33-Copertura!$S$33) -> 0 | J17: =MAX(0,Copertura!$U$34-Copertura!$S$34,Copertura!$U$35-Copertura!$S$35,Copertura!$U$36-Copertura!$S$36,Copertura!$U$37-Copertura!$S$37) -> 0 | K17: =MAX(0,Copertura!$U$38-Copertura!$S$38,Copertura!$U$39-Copertura!$S$39,Copertura!$U$40-Copertura!$S$40,Copertura!$U$41-Copertura!$S$41) -> 0 | L17: =MAX(0,Copertura!$U$42-Copertura!$S$42,Copertura!$U$43-Copertura!$S$43,Copertura!$U$44-Copertura!$S$44,Copertura!$U$45-Copertura!$S$45) -> 0 | M17: =MAX(0,Copertura!$U$46-Copertura!$S$46,Copertura!$U$47-Copertura!$S$47,Copertura!$U$48-Copertura!$S$48,Copertura!$U$49-Copertura!$S$49) -> 0 | N17: =MAX(0,Copertura!$U$50-Copertura!$S$50,Copertura!$U$51-Copertura!$S$51,Copertura!$U$52-Copertura!$S$52,Copertura!$U$53-Copertura!$S$53) -> 0 | O17: =MAX(0,Copertura!$U$54-Copertura!$S$54,Copertura!$U$55-Copertura!$S$55,Copertura!$U$56-Copertura!$S$56,Copertura!$U$57-Copertura!$S$57) -> 0 | P17: =MAX(0,Copertura!$U$58-Copertura!$S$58,Copertura!$U$59-Copertura!$S$59,Copertura!$U$60-Copertura!$S$60,Copertura!$U$61-Copertura!$S$61) -> 1 | Q17: =MAX(0,Copertura!$U$62-Copertura!$S$62,Copertura!$U$63-Copertura!$S$63,Copertura!$U$64-Copertura!$S$64,Copertura!$U$65-Copertura!$S$65) -> 0 | R17: =MAX(0,Copertura!$U$66-Copertura!$S$66,Copertura!$U$67-Copertura!$S$67,Copertura!$U$68-Copertura!$S$68) -> 0
B18: Sab | C18: =MAX(0,Copertura!$Y$6-Copertura!$W$6,Copertura!$Y$7-Copertura!$W$7,Copertura!$Y$8-Copertura!$W$8,Copertura!$Y$9-Copertura!$W$9) -> 0 | D18: =MAX(0,Copertura!$Y$10-Copertura!$W$10,Copertura!$Y$11-Copertura!$W$11,Copertura!$Y$12-Copertura!$W$12,Copertura!$Y$13-Copertura!$W$13) -> 0 | E18: =MAX(0,Copertura!$Y$14-Copertura!$W$14,Copertura!$Y$15-Copertura!$W$15,Copertura!$Y$16-Copertura!$W$16,Copertura!$Y$17-Copertura!$W$17) -> 0 | F18: =MAX(0,Copertura!$Y$18-Copertura!$W$18,Copertura!$Y$19-Copertura!$W$19,Copertura!$Y$20-Copertura!$W$20,Copertura!$Y$21-Copertura!$W$21) -> 0 | G18: =MAX(0,Copertura!$Y$22-Copertura!$W$22,Copertura!$Y$23-Copertura!$W$23,Copertura!$Y$24-Copertura!$W$24,Copertura!$Y$25-Copertura!$W$25) -> 0 | H18: =MAX(0,Copertura!$Y$26-Copertura!$W$26,Copertura!$Y$27-Copertura!$W$27,Copertura!$Y$28-Copertura!$W$28,Copertura!$Y$29-Copertura!$W$29) -> 0 | I18: =MAX(0,Copertura!$Y$30-Copertura!$W$30,Copertura!$Y$31-Copertura!$W$31,Copertura!$Y$32-Copertura!$W$32,Copertura!$Y$33-Copertura!$W$33) -> 0 | J18: =MAX(0,Copertura!$Y$34-Copertura!$W$34,Copertura!$Y$35-Copertura!$W$35,Copertura!$Y$36-Copertura!$W$36,Copertura!$Y$37-Copertura!$W$37) -> 0 | K18: =MAX(0,Copertura!$Y$38-Copertura!$W$38,Copertura!$Y$39-Copertura!$W$39,Copertura!$Y$40-Copertura!$W$40,Copertura!$Y$41-Copertura!$W$41) -> 0 | L18: =MAX(0,Copertura!$Y$42-Copertura!$W$42,Copertura!$Y$43-Copertura!$W$43,Copertura!$Y$44-Copertura!$W$44,Copertura!$Y$45-Copertura!$W$45) -> 0 | M18: =MAX(0,Copertura!$Y$46-Copertura!$W$46,Copertura!$Y$47-Copertura!$W$47,Copertura!$Y$48-Copertura!$W$48,Copertura!$Y$49-Copertura!$W$49) -> 0 | N18: =MAX(0,Copertura!$Y$50-Copertura!$W$50,Copertura!$Y$51-Copertura!$W$51,Copertura!$Y$52-Copertura!$W$52,Copertura!$Y$53-Copertura!$W$53) -> 0 | O18: =MAX(0,Copertura!$Y$54-Copertura!$W$54,Copertura!$Y$55-Copertura!$W$55,Copertura!$Y$56-Copertura!$W$56,Copertura!$Y$57-Copertura!$W$57) -> 0 | P18: =MAX(0,Copertura!$Y$58-Copertura!$W$58,Copertura!$Y$59-Copertura!$W$59,Copertura!$Y$60-Copertura!$W$60,Copertura!$Y$61-Copertura!$W$61) -> 0 | Q18: =MAX(0,Copertura!$Y$62-Copertura!$W$62,Copertura!$Y$63-Copertura!$W$63,Copertura!$Y$64-Copertura!$W$64,Copertura!$Y$65-Copertura!$W$65) -> 0 | R18: =MAX(0,Copertura!$Y$66-Copertura!$W$66,Copertura!$Y$67-Copertura!$W$67,Copertura!$Y$68-Copertura!$W$68) -> 0
B19: Dom | C19: =MAX(0,Copertura!$AC$6-Copertura!$AA$6,Copertura!$AC$7-Copertura!$AA$7,Copertura!$AC$8-Copertura!$AA$8,Copertura!$AC$9-Copertura!$AA$9) -> 0 | D19: =MAX(0,Copertura!$AC$10-Copertura!$AA$10,Copertura!$AC$11-Copertura!$AA$11,Copertura!$AC$12-Copertura!$AA$12,Copertura!$AC$13-Copertura!$AA$13) -> 0 | E19: =MAX(0,Copertura!$AC$14-Copertura!$AA$14,Copertura!$AC$15-Copertura!$AA$15,Copertura!$AC$16-Copertura!$AA$16,Copertura!$AC$17-Copertura!$AA$17) -> 0 | F19: =MAX(0,Copertura!$AC$18-Copertura!$AA$18,Copertura!$AC$19-Copertura!$AA$19,Copertura!$AC$20-Copertura!$AA$20,Copertura!$AC$21-Copertura!$AA$21) -> 0 | G19: =MAX(0,Copertura!$AC$22-Copertura!$AA$22,Copertura!$AC$23-Copertura!$AA$23,Copertura!$AC$24-Copertura!$AA$24,Copertura!$AC$25-Copertura!$AA$25) -> 0 | H19: =MAX(0,Copertura!$AC$26-Copertura!$AA$26,Copertura!$AC$27-Copertura!$AA$27,Copertura!$AC$28-Copertura!$AA$28,Copertura!$AC$29-Copertura!$AA$29) -> 0 | I19: =MAX(0,Copertura!$AC$30-Copertura!$AA$30,Copertura!$AC$31-Copertura!$AA$31,Copertura!$AC$32-Copertura!$AA$32,Copertura!$AC$33-Copertura!$AA$33) -> 0 | J19: =MAX(0,Copertura!$AC$34-Copertura!$AA$34,Copertura!$AC$35-Copertura!$AA$35,Copertura!$AC$36-Copertura!$AA$36,Copertura!$AC$37-Copertura!$AA$37) -> 0 | K19: =MAX(0,Copertura!$AC$38-Copertura!$AA$38,Copertura!$AC$39-Copertura!$AA$39,Copertura!$AC$40-Copertura!$AA$40,Copertura!$AC$41-Copertura!$AA$41) -> 0 | L19: =MAX(0,Copertura!$AC$42-Copertura!$AA$42,Copertura!$AC$43-Copertura!$AA$43,Copertura!$AC$44-Copertura!$AA$44,Copertura!$AC$45-Copertura!$AA$45) -> 0 | M19: =MAX(0,Copertura!$AC$46-Copertura!$AA$46,Copertura!$AC$47-Copertura!$AA$47,Copertura!$AC$48-Copertura!$AA$48,Copertura!$AC$49-Copertura!$AA$49) -> 0 | N19: =MAX(0,Copertura!$AC$50-Copertura!$AA$50,Copertura!$AC$51-Copertura!$AA$51,Copertura!$AC$52-Copertura!$AA$52,Copertura!$AC$53-Copertura!$AA$53) -> 0 | O19: =MAX(0,Copertura!$AC$54-Copertura!$AA$54,Copertura!$AC$55-Copertura!$AA$55,Copertura!$AC$56-Copertura!$AA$56,Copertura!$AC$57-Copertura!$AA$57) -> 0 | P19: =MAX(0,Copertura!$AC$58-Copertura!$AA$58,Copertura!$AC$59-Copertura!$AA$59,Copertura!$AC$60-Copertura!$AA$60,Copertura!$AC$61-Copertura!$AA$61) -> 0 | Q19: =MAX(0,Copertura!$AC$62-Copertura!$AA$62,Copertura!$AC$63-Copertura!$AA$63,Copertura!$AC$64-Copertura!$AA$64,Copertura!$AC$65-Copertura!$AA$65) -> 0 | R19: =MAX(0,Copertura!$AC$66-Copertura!$AA$66,Copertura!$AC$67-Copertura!$AA$67,Copertura!$AC$68-Copertura!$AA$68) -> 0
B20: scuro = coperto · giallo = 1 mancante · rosso = 2+ (fasce orarie 5:30→21:00)
B23: ▍ SCENARIO ASSENZE
B25: ASSENZE | F25: ORE PERSE | J25: RESP OK | N25: DEFICIT
B26: =Personale!$H$41 -> 5 ass. | F26: =Personale!$I$41 -> 140 | J26: =(6-SUMPRODUCT(--(Personale!$B$5:$B$40="RESP"),--(Personale!$H$5:$H$40<>""))) -> 5 | N26: =MAX(0,OreRichieste!$I$17-(Personale!$C$41-Personale!$I$41)) -> 189.76609
B29: =IF((6-SUMPRODUCT(--(Personale!$B$5:$B$40="RESP"),--(Personale!$H$5:$H$40<>"")))<2,"◆ CRITICO — meno di 2 responsabili in servizio",IF(MAX(0,OreRichieste!$I$17-(Personale!$C$41-Personale!$I$41))=0,"● TUTTO OK — copertura garantita, nessun intervento",IF(MAX(0,OreRichieste!$I$17-(Personale!$C$41-Personale!$I$41))<=50,"▲ CHIAMA JOLLY — "&ROUNDUP(MAX(0,OreRichieste!$I$17-(Personale!$C$41-Personale!$I$41))/25,0)&" jolly (su 2) coprono il buco",IF(MAX(0,OreRichieste!$I$17-(Personale!$C$41-Personale!$I$41))<=90,"▲ JOLLY + STRAORD — 2 jolly + "&TEXT(MAX(0,OreRichieste!$I$17-(Personale!$C$41-Personale!$I$41))-50,"0")&"h di straordinario","◆ CRITICO — deficit "&TEXT(MAX(0,OreRichieste!$I$17-(Personale!$C$41-Personale!$I$41)),"0")&"h: oltre 2 jolly + straordinari legali")))) -> ◆ CRITICO — deficit 190h: oltre 2 jolly + straordinari legali
B31: Segna le assenze nel foglio Personale (colonna Assenza: F=ferie, M=malattia). Questo semaforo reagisce dal vivo.
B33: ▸ Fogli: Grafici (Daily Planner + dettaglio) · Turni · Personale (organico + assenze) · Copertura
B34: ▸ Generatore: python generatore_turni.py Modello_Ore_LIDL_v3.xlsx [--auto-ot]

Sheet Home
B2: STORE HOURS ENGINE
B4: Modello ore punto vendita · formato discount LIDL · staff polivalente · v2
B8: ="MODELLO SETTIMANA TIPO: € "&ROUND(Parametri!B5/1000,0)&"k · "&ROUND(Parametri!B6/1000,0)&"k pezzi · "&ROUND(OreRichieste!I17,0)&" ore richieste · KPI in linea: "&COUNTIF(Dashboard!G15:G17,"IN LINEA")&"/3 · Anomalie orario: "&SUM(Dashboard!D54:D59) -> MODELLO SETTIMANA TIPO: € 226k · 136k pezzi · 554 ore richieste · KPI in linea: 2/3 · Anomalie orario: 28
B10: NAVIGAZIONE
B12: DASHBOARD | E12: PERSONALE | H12: TURNI
B14: COPERTURA | E14: PARAMETRI | H14: VOLUMI
B16: CASSE + SCO | E16: ORE RICHIESTE | H16: ORGANICO
B19: COME FUNZIONA
B20: MOTORE | E20: ORARIO DI LAVORO | H20: CONTROLLI VIVI
B21: Ore richieste = volumi x standard a pedana (minuti per PLT) + attivita fisse, per attivita e non per reparto. Front-end dimensionato per fascia oraria (coeff. P75-P80) piu presidio SCO. | E21: Da Personale (organico e monte ore) l'algoritmo genera i Turni: ingresso 5:30 Lun-Gio-Sab e 6:00 gli altri giorni, uscita 21:15, stacco 11h anche sul giro Dom->Lun, aperture e chiusure mai sotto le 2 persone, un responsabile sempre in negozio, part time 25h->5h/g e 30h->6h/g. | H21: Turni e Copertura verificano con formule ogni modifica manuale: slot da 15 minuti presenti vs richiesti, presidio responsabile, stacchi, quadratura monte ore. Semafori riassunti in Dashboard e Home.
B28: LEGENDA E ISTRUZIONI
B29: Testo BLU = input modificabile · Sfondo GIALLO = leve principali · Testo VERDE = formula collegata (non toccare)
B30: 1. Parametri: leve del modello, standard e regole orario di lavoro.
B31: 2. Volumi: calibra % per giorno e profilo per fascia con i dati di cassa reali.
B32: 3. Personale: inserisci organico, ruoli e monte ore.
B33: 4. Turni: orario generato; modificabile a mano, i controlli restano attivi.
B34: 5. Copertura e Dashboard: semafori su coperture, stacchi, aperture/chiusure e produttivita.
B35: Nota: i turni sono valori (blu); i vincoli sono formule vive che segnalano ogni violazione.

Sheet Dashboard
B1: DASHBOARD · STORE HOURS ENGINE
B5: FATTURATO / SETTIMANA | D5: PEZZI VENDUTI / SETTIMANA | F5: ORE RICHIESTE / SETTIMANA
B6: =Parametri!B5 -> 226000 | D6: =Parametri!B6 -> 136000 | F6: =OreRichieste!I17 -> 553.76609
B7: ="Scontrino medio: € "&Parametri!B7 -> Scontrino medio: € 27.77 | D7: ="Scontrini: "&ROUND(Parametri!B8,0) -> Scontrini: 8138 | F7: ="Pianificate: "&ROUND(Organico!I7,0)&" h" -> Pianificate: 553 h
B9: PRODUTTIVITA EUR/ORA | D9: PRODUTTIVITA PEZZI/ORA | F9: INCIDENZA COSTO LAVORO
B10: =IFERROR(Parametri!B5/OreRichieste!I17,"") -> 408.11455 | D10: =IFERROR(Parametri!B6/OreRichieste!I17,"") -> 245.59106 | F10: =IFERROR(Organico!I7*Parametri!B10/Parametri!B5,"") -> 0.053783186
B11: =IF(Parametri!B5/OreRichieste!I17<Parametri!B56,"SOTTO TARGET",IF(Parametri!B5/OreRichieste!I17>Parametri!B57,"SOPRA TARGET","IN LINEA")) -> IN LINEA | D11: =IF(Parametri!B6/OreRichieste!I17<Parametri!B54,"SOTTO TARGET",IF(Parametri!B6/OreRichieste!I17>Parametri!B55,"SOPRA TARGET","IN LINEA")) -> SOTTO TARGET | F11: =IF(Organico!I7*Parametri!B10/Parametri!B5<=Parametri!B58,"IN LINEA","SOPRA SOGLIA") -> IN LINEA
B13: VERIFICA PRODUTTIVITA VS BENCHMARK
B14: Indicatore | D14: Su ore richieste | E14: Su ore PLAN | F14: Target | G14: Esito
B15: Produttivita (EUR/ora) | D15: =IFERROR(Parametri!B5/OreRichieste!I17,"") -> 408.11455 | E15: =IFERROR(Parametri!B5/Organico!I7,"") -> 409.04977 | F15: =Parametri!B56&" - "&Parametri!B57&" €/h" -> 340 - 420 €/h | G15: =IF(D15<Parametri!B56,"SOTTO TARGET",IF(D15>Parametri!B57,"SOPRA TARGET","IN LINEA")) -> IN LINEA
B16: Produttivita (pezzi/ora) | D16: =IFERROR(Parametri!B6/OreRichieste!I17,"") -> 245.59106 | E16: =IFERROR(Parametri!B6/Organico!I7,"") -> 246.15385 | F16: =Parametri!B54&" - "&Parametri!B55&" pz/h" -> 280 - 300 pz/h | G16: =IF(D16<Parametri!B54,"SOTTO TARGET",IF(D16>Parametri!B55,"SOPRA TARGET","IN LINEA")) -> SOTTO TARGET
B17: Incidenza costo lavoro | D17: =IFERROR(OreRichieste!I17*Parametri!B10/Parametri!B5,"") -> 0.053906434 | E17: =IFERROR(Organico!I7*Parametri!B10/Parametri!B5,"") -> 0.053783186 | F17: ="max "&ROUND(Parametri!B58*100,1)&"%" -> max 7% | G17: =IF(D17<=Parametri!B58,"IN LINEA","SOPRA SOGLIA") -> IN LINEA
B19: ORE PER GIORNO · richieste vs pianificate
B20: Giorno | C20: Richieste | D20: Pianificate | E20: Gap | F20: Saturazione
B21: Lun | C21: =OreRichieste!B17 -> 86.038955 | D21: =Organico!B7 -> 86 | E21: =D21-C21 -> -0.038954753 | F21: =IFERROR(C21/D21,"") -> 1.000453
B22: Mar | C22: =OreRichieste!C17 -> 69.028528 | D22: =Organico!C7 -> 69 | E22: =D22-C22 -> -0.028527729 | F22: =IFERROR(C22/D22,"") -> 1.0004134
B23: Mer | C23: =OreRichieste!D17 -> 71.662996 | D23: =Organico!D7 -> 71.5 | E23: =D23-C23 -> -0.16299554 | F23: =IFERROR(C23/D23,"") -> 1.0022797
B24: Gio | C24: =OreRichieste!E17 -> 82.673423 | D24: =Organico!E7 -> 82.5 | E24: =D24-C24 -> -0.17342257 | F24: =IFERROR(C24/D24,"") -> 1.0021021
B25: Ven | C25: =OreRichieste!F17 -> 79.414914 | D25: =Organico!F7 -> 79 | E25: =D25-C25 -> -0.41491396 | F25: =IFERROR(C25/D25,"") -> 1.0052521
B26: Sab | C26: =OreRichieste!G17 -> 94.187686 | D26: =Organico!G7 -> 94 | E26: =D26-C26 -> -0.18768643 | F26: =IFERROR(C26/D26,"") -> 1.0019967
B27: Dom | C27: =OreRichieste!H17 -> 70.759592 | D27: =Organico!H7 -> 70.5 | E27: =D27-C27 -> -0.2595921 | F27: =IFERROR(C27/D27,"") -> 1.0036822
B28: Totale | C28: =OreRichieste!I17 -> 553.76609 | D28: =Organico!I7 -> 552.5 | E28: =D28-C28 -> -1.2660931 | F28: =IFERROR(C28/D28,"") -> 1.0022916
B30: MIX ORE PER ATTIVITA · settimana
B31: Attivita | D31: Ore/sett | E31: % sul totale
B32: =OreRichieste!A4 -> Controllo scorte e ordini merce | D32: =OreRichieste!I4 -> 10.5 | E32: =IFERROR(D32/$D$45,"") -> 0.018961074
B33: =OreRichieste!A5 -> Rifornimento FV | D33: =OreRichieste!I5 -> 29.466667 | E33: =IFERROR(D33/$D$45,"") -> 0.053211396
B34: =OreRichieste!A6 -> BAKE: cottura ed esposizione | D34: =OreRichieste!I6 -> 48.733333 | E34: =IFERROR(D34/$D$45,"") -> 0.088003462
B35: =OreRichieste!A7 -> Rifornimento CARNE | D35: =OreRichieste!I7 -> 8.4722963 | E35: =IFERROR(D35/$D$45,"") -> 0.015299413
B36: =OreRichieste!A8 -> Rifornimento SECCHI | D36: =OreRichieste!I8 -> 49.425369 | E36: =IFERROR(D36/$D$45,"") -> 0.089253151
B37: =OreRichieste!A9 -> Rifornimento SURGELATI | D37: =OreRichieste!I9 -> 10.205867 | E37: =IFERROR(D37/$D$45,"") -> 0.018429923
B38: =OreRichieste!A10 -> Rifornimento FRESCHI | D38: =OreRichieste!I10 -> 23.082681 | E38: =IFERROR(D38/$D$45,"") -> 0.041683088
B39: =OreRichieste!A11 -> Allestimento PROMO FOOD | D39: =OreRichieste!I11 -> 3.7603687 | E39: =IFERROR(D39/$D$45,"") -> 0.0067905361
B40: =OreRichieste!A12 -> Allestimento PROMO NF | D40: =OreRichieste!I12 -> 9.6195122 | E40: =IFERROR(D40/$D$45,"") -> 0.017371075
B41: =OreRichieste!A13 -> Barriera casse | D41: =OreRichieste!I13 -> 190 | E41: =IFERROR(D41/$D$45,"") -> 0.34310515
B42: =OreRichieste!A14 -> Presidio SCO | D42: =OreRichieste!I14 -> 68 | E42: =IFERROR(D42/$D$45,"") -> 0.12279553
B43: =OreRichieste!A15 -> Attivita fisse giornaliere | D43: =OreRichieste!I15 -> 80.5 | E43: =IFERROR(D43/$D$45,"") -> 0.14536824
B44: =OreRichieste!A16 -> Attivita settimanali | D44: =OreRichieste!I16 -> 22 | E44: =IFERROR(D44/$D$45,"") -> 0.039727965
B45: Totale | D45: =OreRichieste!I17 -> 553.76609 | E45: =IFERROR(D45/$D$45,"") -> 1
B47: DETTAGLIO OPERATIVO
B48: Costo del lavoro su ore pianificate | D48: =Organico!I7*Parametri!B10 -> 12155
...

Sheet Personale
A1: ORGANICO E MONTE ORE · input del generatore turni | J1: Costo_orario | K1: Straordinario_sett
A2: Modifica nomi, ruoli e monte ore in blu. Ore/giorno = monte ore / giorni lavorativi (regola part time 25h->5h, 30h->6h).
A4: Dipendente | B4: Ruolo | C4: Monte ore | D4: Giorni lav. | E4: Ore/giorno | F4: Riposi | H4: Assenza | I4: Ore perse | L4: Lun | M4: Mar | N4: Mer | O4: Gio | P4: Ven | Q4: Sab | R4: Dom | S4: OreP
A5: RESP 01 | B5: RESP | C5: 38 | D5: 6 | E5: =IF(D5>0,C5/D5,0) -> 6.3333333 | F5: =7-D5 -> 1 | I5: =IF($H5<>"",$C5,0) -> 0
A6: RESP 02 | B6: RESP | C6: 25 | D6: 6 | E6: =IF(D6>0,C6/D6,0) -> 4.1666667 | F6: =7-D6 -> 1 | I6: =IF($H6<>"",$C6,0) -> 0
A7: RESP 03 | B7: RESP | C7: 25 | D7: 5 | E7: =IF(D7>0,C7/D7,0) -> 5 | F7: =7-D7 -> 2 | I7: =IF($H7<>"",$C7,0) -> 0
A8: RESP 04 | B8: RESP | C8: 25 | D8: 5 | E8: =IF(D8>0,C8/D8,0) -> 5 | F8: =7-D8 -> 2 | I8: =IF($H8<>"",$C8,0) -> 0
A9: RESP 05 | B9: RESP | C9: 40 | D9: 6 | E9: =IF(D9>0,C9/D9,0) -> 6.6666667 | F9: =7-D9 -> 1 | H9: M | I9: =IF($H9<>"",$C9,0) -> 40
A10: RESP 06 | B10: RESP | C10: 25 | D10: 5 | E10: =IF(D10>0,C10/D10,0) -> 5 | F10: =7-D10 -> 2 | I10: =IF($H10<>"",$C10,0) -> 0
A11: RESP 07 | B11: RESP | C11: 25 | D11: 5 | E11: =IF(D11>0,C11/D11,0) -> 5 | F11: =7-D11 -> 2 | I11: =IF($H11<>"",$C11,0) -> 0
A12: ADDETTO 01 | B12: ADDETTO | C12: 25 | D12: 5 | E12: =IF(D12>0,C12/D12,0) -> 5 | F12: =7-D12 -> 2 | I12: =IF($H12<>"",$C12,0) -> 0
A13: ADDETTO 02 | B13: ADDETTO | C13: 20 | D13: 5 | E13: =IF(D13>0,C13/D13,0) -> 4 | F13: =7-D13 -> 2 | I13: =IF($H13<>"",$C13,0) -> 0
A14: ADDETTO 03 | B14: ADDETTO | C14: 25 | D14: 5 | E14: =IF(D14>0,C14/D14,0) -> 5 | F14: =7-D14 -> 2 | I14: =IF($H14<>"",$C14,0) -> 0
A15: ADDETTO 04 | B15: ADDETTO | C15: 25 | D15: 5 | E15: =IF(D15>0,C15/D15,0) -> 5 | F15: =7-D15 -> 2 | I15: =IF($H15<>"",$C15,0) -> 0
A16: ADDETTO 05 | B16: ADDETTO | C16: 25 | D16: 5 | E16: =IF(D16>0,C16/D16,0) -> 5 | F16: =7-D16 -> 2 | I16: =IF($H16<>"",$C16,0) -> 0
A17: ADDETTO 06 | B17: ADDETTO | C17: 25 | D17: 5 | E17: =IF(D17>0,C17/D17,0) -> 5 | F17: =7-D17 -> 2 | I17: =IF($H17<>"",$C17,0) -> 0
A18: ADDETTO 07 | B18: ADDETTO | C18: 25 | D18: 5 | E18: =IF(D18>0,C18/D18,0) -> 5 | F18: =7-D18 -> 2 | I18: =IF($H18<>"",$C18,0) -> 0
A19: ADDETTO 08 | B19: ADDETTO | C19: 25 | D19: 5 | E19: =IF(D19>0,C19/D19,0) -> 5 | F19: =7-D19 -> 2 | I19: =IF($H19<>"",$C19,0) -> 0
A20: ADDETTO 09 | B20: ADDETTO | C20: 30 | D20: 5 | E20: =IF(D20>0,C20/D20,0) -> 6 | F20: =7-D20 -> 2 | I20: =IF($H20<>"",$C20,0) -> 0
A21: ADDETTO 10 | B21: ADDETTO | C21: 25 | D21: 5 | E21: =IF(D21>0,C21/D21,0) -> 5 | F21: =7-D21 -> 2 | I21: =IF($H21<>"",$C21,0) -> 0
A22: ADDETTO 11 | B22: ADDETTO | C22: 25 | D22: 5 | E22: =IF(D22>0,C22/D22,0) -> 5 | F22: =7-D22 -> 2 | H22: M | I22: =IF($H22<>"",$C22,0) -> 25
A23: ADDETTO 12 | B23: ADDETTO | C23: 25 | D23: 5 | E23: =IF(D23>0,C23/D23,0) -> 5 | F23: =7-D23 -> 2 | H23: M | I23: =IF($H23<>"",$C23,0) -> 25
A24: ADDETTO 13 | B24: ADDETTO | C24: 30 | D24: 5 | E24: =IF(D24>0,C24/D24,0) -> 6 | F24: =7-D24 -> 2 | I24: =IF($H24<>"",$C24,0) -> 0
A25: ADDETTO 14 | B25: ADDETTO | C25: 25 | D25: 5 | E25: =IF(D25>0,C25/D25,0) -> 5 | F25: =7-D25 -> 2 | H25: M | I25: =IF($H25<>"",$C25,0) -> 25
A26: ADDETTO 15 | B26: ADDETTO | C26: 25 | D26: 5 | E26: =IF(D26>0,C26/D26,0) -> 5 | F26: =7-D26 -> 2 | I26: =IF($H26<>"",$C26,0) -> 0
A27: ADDETTO 16 | B27: ADDETTO | C27: 20 | D27: 5 | E27: =IF(D27>0,C27/D27,0) -> 4 | F27: =7-D27 -> 2 | I27: =IF($H27<>"",$C27,0) -> 0
A28: ADDETTO 17 | B28: ADDETTO | C28: 25 | D28: 5 | E28: =IF(D28>0,C28/D28,0) -> 5 | F28: =7-D28 -> 2 | H28: M | I28: =IF($H28<>"",$C28,0) -> 25
A29: ADDETTO 18 | B29: ADDETTO | C29: 8 | D29: 1 | E29: =IF(D29>0,C29/D29,0) -> 8 | F29: =7-D29 -> 6 | I29: =IF($H29<>"",$C29,0) -> 0
A30: FRANCESCON | B30: ADDETTO | C30: 8 | D30: 1 | E30: =IF(D30>0,C30/D30,0) -> 8 | F30: =7-D30 -> 6 | I30: =IF($H30<>"",$C30,0) -> 0
E31: =IF(D31>0,C31/D31,0) -> 0 | F31: =7-D31 -> 7 | I31: =IF($H31<>"",$C31,0) -> 0
E32: =IF(D32>0,C32/D32,0) -> 0 | F32: =7-D32 -> 7 | I32: =IF($H32<>"",$C32,0) -> 0
E33: =IF(D33>0,C33/D33,0) -> 0 | F33: =7-D33 -> 7 | I33: =IF($H33<>"",$C33,0) -> 0
E34: =IF(D34>0,C34/D34,0) -> 0 | F34: =7-D34 -> 7 | I34: =IF($H34<>"",$C34,0) -> 0
E35: =IF(D35>0,C35/D35,0) -> 0 | F35: =7-D35 -> 7 | I35: =IF($H35<>"",$C35,0) -> 0
E36: =IF(D36>0,C36/D36,0) -> 0 | F36: =7-D36 -> 7 | I36: =IF($H36<>"",$C36,0) -> 0
E37: =IF(D37>0,C37/D37,0) -> 0 | F37: =7-D37 -> 7 | I37: =IF($H37<>"",$C37,0) -> 0
E38: =IF(D38>0,C38/D38,0) -> 0 | F38: =7-D38 -> 7 | I38: =IF($H38<>"",$C38,0) -> 0
E39: =IF(D39>0,C39/D39,0) -> 0 | F39: =7-D39 -> 7 | I39: =IF($H39<>"",$C39,0) -> 0
E40: =IF(D40>0,C40/D40,0) -> 0 | F40: =7-D40 -> 7 | I40: =IF($H40<>"",$C40,0) -> 0
A41: Totale | B41: =COUNTA(A5:A40)&" teste" -> 26 teste | C41: =SUM(C5:C40)-I31 -> 504 | H41: =COUNTA(H5:H40)&" ass." -> 5 ass. | I41: =SUM(I5:I40) -> 140
...

Sheet Turni
A1: ORARIO DI LAVORO SETTIMANALE · generato dall'algoritmo, modificabile
F3: Lun | I3: Mar | L3: Mer | O3: Gio | R3: Ven | U3: Sab | X3: Dom
A4: Dipendente | B4: Ruolo | C4: Monte | D4: GG | E4: h/g | F4: In | G4: Out | H4: Ore | I4: In | J4: Out | K4: Ore | L4: In | M4: Out | N4: Ore | O4: In | P4: Out | Q4: Ore | R4: In | S4: Out | T4: Ore | U4: In | V4: Out | W4: Ore | X4: In | Y4: Out | Z4: Ore | AA4: Tot | AB4: Delta | AC4: GG | AD4: Stacco
A5: {=IFERROR(INDEX(Personale!$A$5:$A$40,SMALL(IF(Personale!$H$5:$H$40="",ROW(Personale!$A$5:$A$40)-ROW(Personale!$A$5)+1),1)),"")} -> DE PICCOLI | B5: =IFERROR(VLOOKUP($A5,Personale!$A$5:$E$40,2,0),"") -> RESP | C5: =IFERROR(VLOOKUP($A5,Personale!$A$5:$E$40,3,0),0) -> 38 | D5: =IFERROR(VLOOKUP($A5,Personale!$A$5:$E$40,4,0),0) -> 6 | E5: =IFERROR(VLOOKUP($A5,Personale!$A$5:$E$40,5,0),0) -> 6.3333333 | F5: 0.58333333 | G5: 0.83333333 | H5: =IF(AND(ISNUMBER(F5),ISNUMBER(G5)),(G5-F5)*24,0) -> 6 | I5: R | J5: R | K5: =IF(AND(ISNUMBER(I5),ISNUMBER(J5)),(J5-I5)*24,0) -> 0 | L5: 0.45833333 | M5: 0.72916667 | N5: =IF(AND(ISNUMBER(L5),ISNUMBER(M5)),(M5-L5)*24,0) -> 6.5 | O5: 0.61458333 | P5: 0.88541667 | Q5: =IF(AND(ISNUMBER(O5),ISNUMBER(P5)),(P5-O5)*24,0) -> 6.5 | R5: 0.52083333 | S5: 0.83333333 | T5: =IF(AND(ISNUMBER(R5),ISNUMBER(S5)),(S5-R5)*24,0) -> 7.5 | U5: 0.33333333 | V5: 0.58333333 | W5: =IF(AND(ISNUMBER(U5),ISNUMBER(V5)),(V5-U5)*24,0) -> 6 | X5: 0.33333333 | Y5: 0.64583333 | Z5: =IF(AND(ISNUMBER(X5),ISNUMBER(Y5)),(Y5-X5)*24,0) -> 7.5 | AA5: =H5+K5+N5+Q5+T5+W5+Z5 -> 40 | AB5: =AA5-C5 -> 2 | AC5: =(H5>0)+(K5>0)+(N5>0)+(Q5>0)+(T5>0)+(W5>0)+(Z5>0) -> 6 | AD5: =IF(OR(IF(ISNUMBER(G5)*ISNUMBER(I5),(I5+1-G5)*24<Parametri!$B$65),IF(ISNUMBER(J5)*ISNUMBER(L5),(L5+1-J5)*24<Parametri!$B$65),IF(ISNUMBER(M5)*ISNUMBER(O5),(O5+1-M5)*24<Parametri!$B$65),IF(ISNUMBER(P5)*ISNUMBER(R5),(R5+1-P5)*24<Parametri!$B$65),IF(ISNUMBER(S5)*ISNUMBER(U5),(U5+1-S5)*24<Parametri!$B$65),IF(ISNUMBER(V5)*ISNUMBER(X5),(X5+1-V5)*24<Parametri!$B$65),IF(ISNUMBER(Y5)*ISNUMBER(F5),(F5+1-Y5)*24<Parametri!$B$65)),"KO","OK") -> OK
A6: {=IFERROR(INDEX(Personale!$A$5:$A$40,SMALL(IF(Personale!$H$5:$H$40="",ROW(Personale!$A$5:$A$40)-ROW(Personale!$A$5)+1),2)),"")} -> DA PARE’ | B6: =IFERROR(VLOOKUP($A6,Personale!$A$5:$E$40,2,0),"") -> RESP | C6: =IFERROR(VLOOKUP($A6,Personale!$A$5:$E$40,3,0),0) -> 25 | D6: =IFERROR(VLOOKUP($A6,Personale!$A$5:$E$40,4,0),0) -> 6 | E6: =IFERROR(VLOOKUP($A6,Personale!$A$5:$E$40,5,0),0) -> 4.1666667 | F6: 0.69791667 | G6: 0.88541667 | H6: =IF(AND(ISNUMBER(F6),ISNUMBER(G6)),(G6-F6)*24,0) -> 4.5 | I6: 0.63541667 | J6: 0.88541667 | K6: =IF(AND(ISNUMBER(I6),ISNUMBER(J6)),(J6-I6)*24,0) -> 6 | L6: 0.71875 | M6: 0.88541667 | N6: =IF(AND(ISNUMBER(L6),ISNUMBER(M6)),(M6-L6)*24,0) -> 4 | O6: 0.71875 | P6: 0.88541667 | Q6: =IF(AND(ISNUMBER(O6),ISNUMBER(P6)),(P6-O6)*24,0) -> 4 | R6: 0.67708333 | S6: 0.88541667 | T6: =IF(AND(ISNUMBER(R6),ISNUMBER(S6)),(S6-R6)*24,0) -> 5 | U6: 0.71875 | V6: 0.88541667 | W6: =IF(AND(ISNUMBER(U6),ISNUMBER(V6)),(V6-U6)*24,0) -> 4 | X6: R | Y6: R | Z6: =IF(AND(ISNUMBER(X6),ISNUMBER(Y6)),(Y6-X6)*24,0) -> 0 | AA6: =H6+K6+N6+Q6+T6+W6+Z6 -> 27.5 | AB6: =AA6-C6 -> 2.5 | AC6: =(H6>0)+(K6>0)+(N6>0)+(Q6>0)+(T6>0)+(W6>0)+(Z6>0) -> 6 | AD6: =IF(OR(IF(ISNUMBER(G6)*ISNUMBER(I6),(I6+1-G6)*24<Parametri!$B$65),IF(ISNUMBER(J6)*ISNUMBER(L6),(L6+1-J6)*24<Parametri!$B$65),IF(ISNUMBER(M6)*ISNUMBER(O6),(O6+1-M6)*24<Parametri!$B$65),IF(ISNUMBER(P6)*ISNUMBER(R6),(R6+1-P6)*24<Parametri!$B$65),IF(ISNUMBER(S6)*ISNUMBER(U6),(U6+1-S6)*24<Parametri!$B$65),IF(ISNUMBER(V6)*ISNUMBER(X6),(X6+1-V6)*24<Parametri!$B$65),IF(ISNUMBER(Y6)*ISNUMBER(F6),(F6+1-Y6)*24<Parametri!$B$65)),"KO","OK") -> OK
A7: {=IFERROR(INDEX(Personale!$A$5:$A$40,SMALL(IF(Personale!$H$5:$H$40="",ROW(Personale!$A$5:$A$40)-ROW(Personale!$A$5)+1),3)),"")} -> DE PELLEGRIN | B7: =IFERROR(VLOOKUP($A7,Personale!$A$5:$E$40,2,0),"") -> RESP | C7: =IFERROR(VLOOKUP($A7,Personale!$A$5:$E$40,3,0),0) -> 25 | D7: =IFERROR(VLOOKUP($A7,Personale!$A$5:$E$40,4,0),0) -> 5 | E7: =IFERROR(VLOOKUP($A7,Personale!$A$5:$E$40,5,0),0) -> 5 | F7: 0.22916667 | G7: 0.4375 | H7: =IF(AND(ISNUMBER(F7),ISNUMBER(G7)),(G7-F7)*24,0) -> 5 | I7: 0.25 | J7: 0.47916667 | K7: =IF(AND(ISNUMBER(I7),ISNUMBER(J7)),(J7-I7)*24,0) -> 5.5 | L7: R | M7: R | N7: =IF(AND(ISNUMBER(L7),ISNUMBER(M7)),(M7-L7)*24,0) -> 0 | O7: 0.22916667 | P7: 0.45833333 | Q7: =IF(AND(ISNUMBER(O7),ISNUMBER(P7)),(P7-O7)*24,0) -> 5.5 | R7: 0.25 | S7: 0.52083333 | T7: =IF(AND(ISNUMBER(R7),ISNUMBER(S7)),(S7-R7)*24,0) -> 6.5 | U7: 0.22916667 | V7: 0.4375 | W7: =IF(AND(ISNUMBER(U7),ISNUMBER(V7)),(V7-U7)*24,0) -> 5 | X7: R | Y7: R | Z7: =IF(AND(ISNUMBER(X7),ISNUMBER(Y7)),(Y7-X7)*24,0) -> 0 | AA7: =H7+K7+N7+Q7+T7+W7+Z7 -> 27.5 | AB7: =AA7-C7 -> 2.5 | AC7: =(H7>0)+(K7>0)+(N7>0)+(Q7>0)+(T7>0)+(W7>0)+(Z7>0) -> 5 | AD7: =IF(OR(IF(ISNUMBER(G7)*ISNUMBER(I7),(I7+1-G7)*24<Parametri!$B$65),IF(ISNUMBER(J7)*ISNUMBER(L7),(L7+1-J7)*24<Parametri!$B$65),IF(ISNUMBER(M7)*ISNUMBER(O7),(O7+1-M7)*24<Parametri!$B$65),IF(ISNUMBER(P7)*ISNUMBER(R7),(R7+1-P7)*24<Parametri!$B$65),IF(ISNUMBER(S7)*ISNUMBER(U7),(U7+1-S7)*24<Parametri!$B$65),IF(ISNUMBER(V7)*ISNUMBER(X7),(X7+1-V7)*24<Parametri!$B$65),IF(ISNUMBER(Y7)*ISNUMBER(F7),(F7+1-Y7)*24<Parametri!$B$65)),"KO","OK") -> OK
A8: {=IFERROR(INDEX(Personale!$A$5:$A$40,SMALL(IF(Personale!$H$5:$H$40="",ROW(Personale!$A$5:$A$40)-ROW(Personale!$A$5)+1),4)),"")} -> DUBON | B8: =IFERROR(VLOOKUP($A8,Personale!$A$5:$E$40,2,0),"") -> RESP | C8: =IFERROR(VLOOKUP($A8,Personale!$A$5:$E$40,3,0),0) -> 25 | D8: =IFERROR(VLOOKUP($A8,Personale!$A$5:$E$40,4,0),0) -> 5 | E8: =IFERROR(VLOOKUP($A8,Personale!$A$5:$E$40,5,0),0) -> 5 | F8: 0.47916667 | G8: 0.6875 | H8: =IF(AND(ISNUMBER(F8),ISNUMBER(G8)),(G8-F8)*24,0) -> 5 | I8: R | J8: R | K8: =IF(AND(ISNUMBER(I8),ISNUMBER(J8)),(J8-I8)*24,0) -> 0 | L8: R | M8: R | N8: =IF(AND(ISNUMBER(L8),ISNUMBER(M8)),(M8-L8)*24,0) -> 0 | O8: 0.41666667 | P8: 0.625 | Q8: =IF(AND(ISNUMBER(O8),ISNUMBER(P8)),(P8-O8)*24,0) -> 5 | R8: 0.25 | S8: 0.47916667 | T8: =IF(AND(ISNUMBER(R8),ISNUMBER(S8)),(S8-R8)*24,0) -> 5.5 | U8: 0.67708333 | V8: 0.88541667 | W8: =IF(AND(ISNUMBER(U8),ISNUMBER(V8)),(V8-U8)*24,0) -> 5 | X8: 0.59375 | Y8: 0.88541667 | Z8: =IF(AND(ISNUMBER(X8),ISNUMBER(Y8)),(Y8-X8)*24,0) -> 7 | AA8: =H8+K8+N8+Q8+T8+W8+Z8 -> 27.5 | AB8: =AA8-C8 -> 2.5 | AC8: =(H8>0)+(K8>0)+(N8>0)+(Q8>0)+(T8>0)+(W8>0)+(Z8>0) -> 5 | AD8: =IF(OR(IF(ISNUMBER(G8)*ISNUMBER(I8),(I8+1-G8)*24<Parametri!$B$65),IF(ISNUMBER(J8)*ISNUMBER(L8),(L8+1-J8)*24<Parametri!$B$65),IF(ISNUMBER(M8)*ISNUMBER(O8),(O8+1-M8)*24<Parametri!$B$65),IF(ISNUMBER(P8)*ISNUMBER(R8),(R8+1-P8)*24<Parametri!$B$65),IF(ISNUMBER(S8)*ISNUMBER(U8),(U8+1-S8)*24<Parametri!$B$65),IF(ISNUMBER(V8)*ISNUMBER(X8),(X8+1-V8)*24<Parametri!$B$65),IF(ISNUMBER(Y8)*ISNUMBER(F8),(F8+1-Y8)*24<Parametri!$B$65)),"KO","OK") -> OK
A9: {=IFERROR(INDEX(Personale!$A$5:$A$40,SMALL(IF(Personale!$H$5:$H$40="",ROW(Personale!$A$5:$A$40)-ROW(Personale!$A$5)+1),5)),"")} -> MUNERATI | B9: =IFERROR(VLOOKUP($A9,Personale!$A$5:$E$40,2,0),"") -> RESP | C9: =IFERROR(VLOOKUP($A9,Personale!$A$5:$E$40,3,0),0) -> 25 | D9: =IFERROR(VLOOKUP($A9,Personale!$A$5:$E$40,4,0),0) -> 5 | E9: =IFERROR(VLOOKUP($A9,Personale!$A$5:$E$40,5,0),0) -> 5 | F9: 0.22916667 | G9: 0.4375 | H9: =IF(AND(ISNUMBER(F9),ISNUMBER(G9)),(G9-F9)*24,0) -> 5 | I9: 0.47916667 | J9: 0.6875 | K9: =IF(AND(ISNUMBER(I9),ISNUMBER(J9)),(J9-I9)*24,0) -> 5 | L9: 0.25 | M9: 0.47916667 | N9: =IF(AND(ISNUMBER(L9),ISNUMBER(M9)),(M9-L9)*24,0) -> 5.5 | O9: 0.22916667 | P9: 0.5 | Q9: =IF(AND(ISNUMBER(O9),ISNUMBER(P9)),(P9-O9)*24,0) -> 6.5 | R9: R | S9: R | T9: =IF(AND(ISNUMBER(R9),ISNUMBER(S9)),(S9-R9)*24,0) -> 0 | U9: 0.22916667 | V9: 0.45833333 | W9: =IF(AND(ISNUMBER(U9),ISNUMBER(V9)),(V9-U9)*24,0) -> 5.5 | X9: R | Y9: R | Z9: =IF(AND(ISNUMBER(X9),ISNUMBER(Y9)),(Y9-X9)*24,0) -> 0 | AA9: =H9+K9+N9+Q9+T9+W9+Z9 -> 27.5 | AB9: =AA9-C9 -> 2.5 | AC9: =(H9>0)+(K9>0)+(N9>0)+(Q9>0)+(T9>0)+(W9>0)+(Z9>0) -> 5 | AD9: =IF(OR(IF(ISNUMBER(G9)*ISNUMBER(I9),(I9+1-G9)*24<Parametri!$B$65),IF(ISNUMBER(J9)*ISNUMBER(L9),(L9+1-J9)*24<Parametri!$B$65),IF(ISNUMBER(M9)*ISNUMBER(O9),(O9+1-M9)*24<Parametri!$B$65),IF(ISNUMBER(P9)*ISNUMBER(R9),(R9+1-P9)*24<Parametri!$B$65),IF(ISNUMBER(S9)*ISNUMBER(U9),(U9+1-S9)*24<Parametri!$B$65),IF(ISNUMBER(V9)*ISNUMBER(X9),(X9+1-V9)*24<Parametri!$B$65),IF(ISNUMBER(Y9)*ISNUMBER(F9),(F9+1-Y9)*24<Parametri!$B$65)),"KO","OK") -> OK
A10: {=IFERROR(INDEX(Personale!$A$5:$A$40,SMALL(IF(Personale!$H$5:$H$40="",ROW(Personale!$A$5:$A$40)-ROW(Personale!$A$5)+1),6)),"")} -> SEGAT | B10: =IFERROR(VLOOKUP($A10,Personale!$A$5:$E$40,2,0),"") -> RESP | C10: =IFERROR(VLOOKUP($A10,Personale!$A$5:$E$40,3,0),0) -> 25 | D10: =IFERROR(VLOOKUP($A10,Personale!$A$5:$E$40,4,0),0) -> 5 | E10: =IFERROR(VLOOKUP($A10,Personale!$A$5:$E$40,5,0),0) -> 5 | F10: 0.22916667 | G10: 0.47916667 | H10: =IF(AND(ISNUMBER(F10),ISNUMBER(G10)),(G10-F10)*24,0) -> 6 | I10: R | J10: R | K10: =IF(AND(ISNUMBER(I10),ISNUMBER(J10)),(J10-I10)*24,0) -> 0 | L10: R | M10: R | N10: =IF(AND(ISNUMBER(L10),ISNUMBER(M10)),(M10-L10)*24,0) -> 0 | O10: 0.22916667 | P10: 0.45833333 | Q10: =IF(AND(ISNUMBER(O10),ISNUMBER(P10)),(P10-O10)*24,0) -> 5.5 | R10: 0.47916667 | S10: 0.6875 | T10: =IF(AND(ISNUMBER(R10),ISNUMBER(S10)),(S10-R10)*24,0) -> 5 | U10: 0.5 | V10: 0.70833333 | W10: =IF(AND(ISNUMBER(U10),ISNUMBER(V10)),(V10-U10)*24,0) -> 5 | X10: 0.25 | Y10: 0.5 | Z10: =IF(AND(ISNUMBER(X10),ISNUMBER(Y10)),(Y10-X10)*24,0) -> 6 | AA10: =H10+K10+N10+Q10+T10+W10+Z10 -> 27.5 | AB10: =AA10-C10 -> 2.5 | AC10: =(H10>0)+(K10>0)+(N10>0)+(Q10>0)+(T10>0)+(W10>0)+(Z10>0) -> 5 | AD10: =IF(OR(IF(ISNUMBER(G10)*ISNUMBER(I10),(I10+1-G10)*24<Parametri!$B$65),IF(ISNUMBER(J10)*ISNUMBER(L10),(L10+1-J10)*24<Parametri!$B$65),IF(ISNUMBER(M10)*ISNUMBER(O10),(O10+1-M10)*24<Parametri!$B$65),IF(ISNUMBER(P10)*ISNUMBER(R10),(R10+1-P10)*24<Parametri!$B$65),IF(ISNUMBER(S10)*ISNUMBER(U10),(U10+1-S10)*24<Parametri!$B$65),IF(ISNUMBER(V10)*ISNUMBER(X10),(X10+1-V10)*24<Parametri!$B$65),IF(ISNUMBER(Y10)*ISNUMBER(F10),(F10+1-Y10)*24<Parametri!$B$65)),"KO","OK") -> OK
A11: {=IFERROR(INDEX(Personale!$A$5:$A$40,SMALL(IF(Personale!$H$5:$H$40="",ROW(Personale!$A$5:$A$40)-ROW(Personale!$A$5)+1),7)),"")} -> ANDREOLI | B11: =IFERROR(VLOOKUP($A11,Personale!$A$5:$E$40,2,0),"") -> ADDETTO | C11: =IFERROR(VLOOKUP($A11,Personale!$A$5:$E$40,3,0),0) -> 25 | D11: =IFERROR(VLOOKUP($A11,Personale!$A$5:$E$40,4,0),0) -> 5 | E11: =IFERROR(VLOOKUP($A11,Personale!$A$5:$E$40,5,0),0) -> 5 | F11: R | G11: R | H11: =IF(AND(ISNUMBER(F11),ISNUMBER(G11)),(G11-F11)*24,0) -> 0 | I11: R | J11: R | K11: =IF(AND(ISNUMBER(I11),ISNUMBER(J11)),(J11-I11)*24,0) -> 0 | L11: 0.61458333 | M11: 0.88541667 | N11: =IF(AND(ISNUMBER(L11),ISNUMBER(M11)),(M11-L11)*24,0) -> 6.5 | O11: 0.67708333 | P11: 0.88541667 | Q11: =IF(AND(ISNUMBER(O11),ISNUMBER(P11)),(P11-O11)*24,0) -> 5 | R11: 0.58333333 | S11: 0.83333333 | T11: =IF(AND(ISNUMBER(R11),ISNUMBER(S11)),(S11-R11)*24,0) -> 6 | U11: 0.625 | V11: 0.83333333 | W11: =IF(AND(ISNUMBER(U11),ISNUMBER(V11)),(V11-U11)*24,0) -> 5 | X11: 0.47916667 | Y11: 0.6875 | Z11: =IF(AND(ISNUMBER(X11),ISNUMBER(Y11)),(Y11-X11)*24,0) -> 5 | AA11: =H11+K11+N11+Q11+T11+W11+Z11 -> 27.5 | AB11: =AA11-C11 -> 2.5 | AC11: =(H11>0)+(K11>0)+(N11>0)+(Q11>0)+(T11>0)+(W11>0)+(Z11>0) -> 5 | AD11: =IF(OR(IF(ISNUMBER(G11)*ISNUMBER(I11),(I11+1-G11)*24<Parametri!$B$65),IF(ISNUMBER(J11)*ISNUMBER(L11),(L11+1-J11)*24<Parametri!$B$65),IF(ISNUMBER(M11)*ISNUMBER(O11),(O11+1-M11)*24<Parametri!$B$65),IF(ISNUMBER(P11)*ISNUMBER(R11),(R11+1-P11)*24<Parametri!$B$65),IF(ISNUMBER(S11)*ISNUMBER(U11),(U11+1-S11)*24<Parametri!$B$65),IF(ISNUMBER(V11)*ISNUMBER(X11),(X11+1-V11)*24<Parametri!$B$65),IF(ISNUMBER(Y11)*ISNUMBER(F11),(F11+1-Y11)*24<Parametri!$B$65)),"KO","OK") -> OK
A12: {=IFERROR(INDEX(Personale!$A$5:$A$40,SMALL(IF(Personale!$H$5:$H$40="",ROW(Personale!$A$5:$A$40)-ROW(Personale!$A$5)+1),8)),"")} -> BELLUCCO | B12: =IFERROR(VLOOKUP($A12,Personale!$A$5:$E$40,2,0),"") -> ADDETTO | C12: =IFERROR(VLOOKUP($A12,Personale!$A$5:$E$40,3,0),0) -> 20 | D12: =IFERROR(VLOOKUP($A12,Personale!$A$5:$E$40,4,0),0) -> 5 | E12: =IFERROR(VLOOKUP($A12,Personale!$A$5:$E$40,5,0),0) -> 4 | F12: 0.69791667 | G12: 0.88541667 | H12: =IF(AND(ISNUMBER(F12),ISNUMBER(G12)),(G12-F12)*24,0) -> 4.5 | I12: R | J12: R | K12: =IF(AND(ISNUMBER(I12),ISNUMBER(J12)),(J12-I12)*24,0) -> 0 | L12: 0.25 | M12: 0.45833333 | N12: =IF(AND(ISNUMBER(L12),ISNUMBER(M12)),(M12-L12)*24,0) -> 5 | O12: R | P12: R | Q12: =IF(AND(ISNUMBER(O12),ISNUMBER(P12)),(P12-O12)*24,0) -> 0 | R12: 0.25 | S12: 0.41666667 | T12: =IF(AND(ISNUMBER(R12),ISNUMBER(S12)),(S12-R12)*24,0) -> 4 | U12: 0.22916667 | V12: 0.39583333 | W12: =IF(AND(ISNUMBER(U12),ISNUMBER(V12)),(V12-U12)*24,0) -> 4 | X12: 0.625 | Y12: 0.83333333 | Z12: =IF(AND(ISNUMBER(X12),ISNUMBER(Y12)),(Y12-X12)*24,0) -> 5 | AA12: =H12+K12+N12+Q12+T12+W12+Z12 -> 22.5 | AB12: =AA12-C12 -> 2.5 | AC12: =(H12>0)+(K12>0)+(N12>0)+(Q12>0)+(T12>0)+(W12>0)+(Z12>0) -> 5 | AD12: =IF(OR(IF(ISNUMBER(G12)*ISNUMBER(I12),(I12+1-G12)*24<Parametri!$B$65),IF(ISNUMBER(J12)*ISNUMBER(L12),(L12+1-J12)*24<Parametri!$B$65),IF(ISNUMBER(M12)*ISNUMBER(O12),(O12+1-M12)*24<Parametri!$B$65),IF(ISNUMBER(P12)*ISNUMBER(R12),(R12+1-P12)*24<Parametri!$B$65),IF(ISNUMBER(S12)*ISNUMBER(U12),(U12+1-S12)*24<Parametri!$B$65),IF(ISNUMBER(V12)*ISNUMBER(X12),(X12+1-V12)*24<Parametri!$B$65),IF(ISNUMBER(Y12)*ISNUMBER(F12),(F12+1-Y12)*24<Parametri!$B$65)),"KO","OK") -> OK
A13: {=IFERROR(INDEX(Personale!$A$5:$A$40,SMALL(IF(Personale!$H$5:$H$40="",ROW(Personale!$A$5:$A$40)-ROW(Personale!$A$5)+1),9)),"")} -> BUORO | B13: =IFERROR(VLOOKUP($A13,Personale!$A$5:$E$40,2,0),"") -> ADDETTO | C13: =IFERROR(VLOOKUP($A13,Personale!$A$5:$E$40,3,0),0) -> 25 | D13: =IFERROR(VLOOKUP($A13,Personale!$A$5:$E$40,4,0),0) -> 5 | E13: =IFERROR(VLOOKUP($A13,Personale!$A$5:$E$40,5,0),0) -> 5 | F13: 0.45833333 | G13: 0.70833333 | H13: =IF(AND(ISNUMBER(F13),ISNUMBER(G13)),(G13-F13)*24,0) -> 6 | I13: 0.5625 | J13: 0.83333333 | K13: =IF(AND(ISNUMBER(I13),ISNUMBER(J13)),(J13-I13)*24,0) -> 6.5 | L13: R | M13: R | N13: =IF(AND(ISNUMBER(L13),ISNUMBER(M13)),(M13-L13)*24,0) -> 0 | O13: 0.22916667 | P13: 0.4375 | Q13: =IF(AND(ISNUMBER(O13),ISNUMBER(P13)),(P13-O13)*24,0) -> 5 | R13: 0.67708333 | S13: 0.88541667 | T13: =IF(AND(ISNUMBER(R13),ISNUMBER(S13)),(S13-R13)*24,0) -> 5 | U13: R | V13: R | W13: =IF(AND(ISNUMBER(U13),ISNUMBER(V13)),(V13-U13)*24,0) -> 0 | X13: 0.54166667 | Y13: 0.75 | Z13: =IF(AND(ISNUMBER(X13),ISNUMBER(Y13)),(Y13-X13)*24,0) -> 5 | AA13: =H13+K13+N13+Q13+T13+W13+Z13 -> 27.5 | AB13: =AA13-C13 -> 2.5 | AC13: =(H13>0)+(K13>0)+(N13>0)+(Q13>0)+(T13>0)+(W13>0)+(Z13>0) -> 5 | AD13: =IF(OR(IF(ISNUMBER(G13)*ISNUMBER(I13),(I13+1-G13)*24<Parametri!$B$65),IF(ISNUMBER(J13)*ISNUMBER(L13),(L13+1-J13)*24<Parametri!$B$65),IF(ISNUMBER(M13)*ISNUMBER(O13),(O13+1-M13)*24<Parametri!$B$65),IF(ISNUMBER(P13)*ISNUMBER(R13),(R13+1-P13)*24<Parametri!$B$65),IF(ISNUMBER(S13)*ISNUMBER(U13),(U13+1-S13)*24<Parametri!$B$65),IF(ISNUMBER(V13)*ISNUMBER(X13),(X13+1-V13)*24<Parametri!$B$65),IF(ISNUMBER(Y13)*ISNUMBER(F13),(F13+1-Y13)*24<Parametri!$B$65)),"KO","OK") -> OK
A14: {=IFERROR(INDEX(Personale!$A$5:$A$40,SMALL(IF(Personale!$H$5:$H$40="",ROW(Personale!$A$5:$A$40)-ROW(Personale!$A$5)+1),10)),"")} -> CANOVA | B14: =IFERROR(VLOOKUP($A14,Personale!$A$5:$E$40,2,0),"") -> ADDETTO | C14: =IFERROR(VLOOKUP($A14,Personale!$A$5:$E$40,3,0),0) -> 25 | D14: =IFERROR(VLOOKUP($A14,Personale!$A$5:$E$40,4,0),0) -> 5 | E14: =IFERROR(VLOOKUP($A14,Personale!$A$5:$E$40,5,0),0) -> 5 | F14: 0.67708333 | G14: 0.88541667 | H14: =IF(AND(ISNUMBER(F14),ISNUMBER(G14)),(G14-F14)*24,0) -> 5 | I14: R | J14: R | K14: =IF(AND(ISNUMBER(I14),ISNUMBER(J14)),(J14-I14)*24,0) -> 0 | L14: 0.47916667 | M14: 0.6875 | N14: =IF(AND(ISNUMBER(L14),ISNUMBER(M14)),(M14-L14)*24,0) -> 5 | O14: R | P14: R | Q14: =IF(AND(ISNUMBER(O14),ISNUMBER(P14)),(P14-O14)*24,0) -> 0 | R14: 0.41666667 | S14: 0.6875 | T14: =IF(AND(ISNUMBER(R14),ISNUMBER(S14)),(S14-R14)*24,0) -> 6.5 | U14: 0.22916667 | V14: 0.4375 | W14: =IF(AND(ISNUMBER(U14),ISNUMBER(V14)),(V14-U14)*24,0) -> 5 | X14: 0.35416667 | Y14: 0.60416667 | Z14: =IF(AND(ISNUMBER(X14),ISNUMBER(Y14)),(Y14-X14)*24,0) -> 6 | AA14: =H14+K14+N14+Q14+T14+W14+Z14 -> 27.5 | AB14: =AA14-C14 -> 2.5 | AC14: =(H14>0)+(K14>0)+(N14>0)+(Q14>0)+(T14>0)+(W14>0)+(Z14>0) -> 5 | AD14: =IF(OR(IF(ISNUMBER(G14)*ISNUMBER(I14),(I14+1-G14)*24<Parametri!$B$65),IF(ISNUMBER(J14)*ISNUMBER(L14),(L14+1-J14)*24<Parametri!$B$65),IF(ISNUMBER(M14)*ISNUMBER(O14),(O14+1-M14)*24<Parametri!$B$65),IF(ISNUMBER(P14)*ISNUMBER(R14),(R14+1-P14)*24<Parametri!$B$65),IF(ISNUMBER(S14)*ISNUMBER(U14),(U14+1-S14)*24<Parametri!$B$65),IF(ISNUMBER(V14)*ISNUMBER(X14),(X14+1-V14)*24<Parametri!$B$65),IF(ISNUMBER(Y14)*ISNUMBER(F14),(F14+1-Y14)*24<Parametri!$B$65)),"KO","OK") -> OK
A15: {=IFERROR(INDEX(Personale!$A$5:$A$40,SMALL(IF(Personale!$H$5:$H$40="",ROW(Personale!$A$5:$A$40)-ROW(Personale!$A$5)+1),11)),"")} -> CHIERZI | B15: =IFERROR(VLOOKUP($A15,Personale!$A$5:$E$40,2,0),"") -> ADDETTO | C15: =IFERROR(VLOOKUP($A15,Personale!$A$5:$E$40,3,0),0) -> 25 | D15: =IFERROR(VLOOKUP($A15,Personale!$A$5:$E$40,4,0),0) -> 5 | E15: =IFERROR(VLOOKUP($A15,Personale!$A$5:$E$40,5,0),0) -> 5 | F15: 0.22916667 | G15: 0.4375 | H15: =IF(AND(ISNUMBER(F15),ISNUMBER(G15)),(G15-F15)*24,0) -> 5 | I15: 0.25 | J15: 0.5 | K15: =IF(AND(ISNUMBER(I15),ISNUMBER(J15)),(J15-I15)*24,0) -> 6 | L15: 0.66666667 | M15: 0.875 | N15: =IF(AND(ISNUMBER(L15),ISNUMBER(M15)),(M15-L15)*24,0) -> 5 | O15: 0.5625 | P15: 0.8125 | Q15: =IF(AND(ISNUMBER(O15),ISNUMBER(P15)),(P15-O15)*24,0) -> 6 | R15: R | S15: R | T15: =IF(AND(ISNUMBER(R15),ISNUMBER(S15)),(S15-R15)*24,0) -> 0 | U15: 0.60416667 | V15: 0.83333333 | W15: =IF(AND(ISNUMBER(U15),ISNUMBER(V15)),(V15-U15)*24,0) -> 5.5 | X15: R | Y15: R | Z15: =IF(AND(ISNUMBER(X15),ISNUMBER(Y15)),(Y15-X15)*24,0) -> 0 | AA15: =H15+K15+N15+Q15+T15+W15+Z15 -> 27.5 | AB15: =AA15-C15 -> 2.5 | AC15: =(H15>0)+(K15>0)+(N15>0)+(Q15>0)+(T15>0)+(W15>0)+(Z15>0) -> 5 | AD15: =IF(OR(IF(ISNUMBER(G15)*ISNUMBER(I15),(I15+1-G15)*24<Parametri!$B$65),IF(ISNUMBER(J15)*ISNUMBER(L15),(L15+1-J15)*24<Parametri!$B$65),IF(ISNUMBER(M15)*ISNUMBER(O15),(O15+1-M15)*24<Parametri!$B$65),IF(ISNUMBER(P15)*ISNUMBER(R15),(R15+1-P15)*24<Parametri!$B$65),IF(ISNUMBER(S15)*ISNUMBER(U15),(U15+1-S15)*24<Parametri!$B$65),IF(ISNUMBER(V15)*ISNUMBER(X15),(X15+1-V15)*24<Parametri!$B$65),IF(ISNUMBER(Y15)*ISNUMBER(F15),(F15+1-Y15)*24<Parametri!$B$65)),"KO","OK") -> OK
A16: {=IFERROR(INDEX(Personale!$A$5:$A$40,SMALL(IF(Personale!$H$5:$H$40="",ROW(Personale!$A$5:$A$40)-ROW(Personale!$A$5)+1),12)),"")} -> BUGRYM | B16: =IFERROR(VLOOKUP($A16,Personale!$A$5:$E$40,2,0),"") -> ADDETTO | C16: =IFERROR(VLOOKUP($A16,Personale!$A$5:$E$40,3,0),0) -> 25 | D16: =IFERROR(VLOOKUP($A16,Personale!$A$5:$E$40,4,0),0) -> 5 | E16: =IFERROR(VLOOKUP($A16,Personale!$A$5:$E$40,5,0),0) -> 5 | F16: R | G16: R | H16: =IF(AND(ISNUMBER(F16),ISNUMBER(G16)),(G16-F16)*24,0) -> 0 | I16: 0.52083333 | J16: 0.75 | K16: =IF(AND(ISNUMBER(I16),ISNUMBER(J16)),(J16-I16)*24,0) -> 5.5 | L16: R | M16: R | N16: =IF(AND(ISNUMBER(L16),ISNUMBER(M16)),(M16-L16)*24,0) -> 0 | O16: 0.45833333 | P16: 0.6875 | Q16: =IF(AND(ISNUMBER(O16),ISNUMBER(P16)),(P16-O16)*24,0) -> 5.5 | R16: 0.5625 | S16: 0.77083333 | T16: =IF(AND(ISNUMBER(R16),ISNUMBER(S16)),(S16-R16)*24,0) -> 5 | U16: 0.67708333 | V16: 0.88541667 | W16: =IF(AND(ISNUMBER(U16),ISNUMBER(V16)),(V16-U16)*24,0) -> 5 | X16: 0.61458333 | Y16: 0.88541667 | Z16: =IF(AND(ISNUMBER(X16),ISNUMBER(Y16)),(Y16-X16)*24,0) -> 6.5 | AA16: =H16+K16+N16+Q16+T16+W16+Z16 -> 27.5 | AB16: =AA16-C16 -> 2.5 | AC16: =(H16>0)+(K16>0)+(N16>0)+(Q16>0)+(T16>0)+(W16>0)+(Z16>0) -> 5 | AD16: =IF(OR(IF(ISNUMBER(G16)*ISNUMBER(I16),(I16+1-G16)*24<Parametri!$B$65),IF(ISNUMBER(J16)*ISNUMBER(L16),(L16+1-J16)*24<Parametri!$B$65),IF(ISNUMBER(M16)*ISNUMBER(O16),(O16+1-M16)*24<Parametri!$B$65),IF(ISNUMBER(P16)*ISNUMBER(R16),(R16+1-P16)*24<Parametri!$B$65),IF(ISNUMBER(S16)*ISNUMBER(U16),(U16+1-S16)*24<Parametri!$B$65),IF(ISNUMBER(V16)*ISNUMBER(X16),(X16+1-V16)*24<Parametri!$B$65),IF(ISNUMBER(Y16)*ISNUMBER(F16),(F16+1-Y16)*24<Parametri!$B$65)),"KO","OK") -> OK
A17: {=IFERROR(INDEX(Personale!$A$5:$A$40,SMALL(IF(Personale!$H$5:$H$40="",ROW(Personale!$A$5:$A$40)-ROW(Personale!$A$5)+1),13)),"")} -> DAL ZOT | B17: =IFERROR(VLOOKUP($A17,Personale!$A$5:$E$40,2,0),"") -> ADDETTO | C17: =IFERROR(VLOOKUP($A17,Personale!$A$5:$E$40,3,0),0) -> 25 | D17: =IFERROR(VLOOKUP($A17,Personale!$A$5:$E$40,4,0),0) -> 5 | E17: =IFERROR(VLOOKUP($A17,Personale!$A$5:$E$40,5,0),0) -> 5 | F17: 0.41666667 | G17: 0.625 | H17: =IF(AND(ISNUMBER(F17),ISNUMBER(G17)),(G17-F17)*24,0) -> 5 | I17: 0.25 | J17: 0.45833333 | K17: =IF(AND(ISNUMBER(I17),ISNUMBER(J17)),(J17-I17)*24,0) -> 5 | L17: 0.25 | M17: 0.54166667 | N17: =IF(AND(ISNUMBER(L17),ISNUMBER(M17)),(M17-L17)*24,0) -> 7 | O17: R | P17: R | Q17: =IF(AND(ISNUMBER(O17),ISNUMBER(P17)),(P17-O17)*24,0) -> 0 | R17: 0.33333333 | S17: 0.5625 | T17: =IF(AND(ISNUMBER(R17),ISNUMBER(S17)),(S17-R17)*24,0) -> 5.5 | U17: R | V17: R | W17: =IF(AND(ISNUMBER(U17),ISNUMBER(V17)),(V17-U17)*24,0) -> 0 | X17: 0.67708333 | Y17: 0.88541667 | Z17: =IF(AND(ISNUMBER(X17),ISNUMBER(Y17)),(Y17-X17)*24,0) -> 5 | AA17: =H17+K17+N17+Q17+T17+W17+Z17 -> 27.5 | AB17: =AA17-C17 -> 2.5 | AC17: =(H17>0)+(K17>0)+(N17>0)+(Q17>0)+(T17>0)+(W17>0)+(Z17>0) -> 5 | AD17: =IF(OR(IF(ISNUMBER(G17)*ISNUMBER(I17),(I17+1-G17)*24<Parametri!$B$65),IF(ISNUMBER(J17)*ISNUMBER(L17),(L17+1-J17)*24<Parametri!$B$65),IF(ISNUMBER(M17)*ISNUMBER(O17),(O17+1-M17)*24<Parametri!$B$65),IF(ISNUMBER(P17)*ISNUMBER(R17),(R17+1-P17)*24<Parametri!$B$65),IF(ISNUMBER(S17)*ISNUMBER(U17),(U17+1-S17)*24<Parametri!$B$65),IF(ISNUMBER(V17)*ISNUMBER(X17),(X17+1-V17)*24<Parametri!$B$65),IF(ISNUMBER(Y17)*ISNUMBER(F17),(F17+1-Y17)*24<Parametri!$B$65)),"KO","OK") -> OK
A18: {=IFERROR(INDEX(Personale!$A$5:$A$40,SMALL(IF(Personale!$H$5:$H$40="",ROW(Personale!$A$5:$A$40)-ROW(Personale!$A$5)+1),14)),"")} -> DE NARDIN | B18: =IFERROR(VLOOKUP($A18,Personale!$A$5:$E$40,2,0),"") -> ADDETTO | C18: =IFERROR(VLOOKUP($A18,Personale!$A$5:$E$40,3,0),0) -> 25 | D18: =IFERROR(VLOOKUP($A18,Personale!$A$5:$E$40,4,0),0) -> 5 | E18: =IFERROR(VLOOKUP($A18,Personale!$A$5:$E$40,5,0),0) -> 5 | F18: 0.22916667 | G18: 0.47916667 | H18: =IF(AND(ISNUMBER(F18),ISNUMBER(G18)),(G18-F18)*24,0) -> 6 | I18: R | J18: R | K18: =IF(AND(ISNUMBER(I18),ISNUMBER(J18)),(J18-I18)*24,0) -> 0 | L18: 0.625 | M18: 0.83333333 | N18: =IF(AND(ISNUMBER(L18),ISNUMBER(M18)),(M18-L18)*24,0) -> 5 | O18: 0.33333333 | P18: 0.5625 | Q18: =IF(AND(ISNUMBER(O18),ISNUMBER(P18)),(P18-O18)*24,0) -> 5.5 | R18: R | S18: R | T18: =IF(AND(ISNUMBER(R18),ISNUMBER(S18)),(S18-R18)*24,0) -> 0 | U18: 0.45833333 | V18: 0.6875 | W18: =IF(AND(ISNUMBER(U18),ISNUMBER(V18)),(V18-U18)*24,0) -> 5.5 | X18: 0.25 | Y18: 0.47916667 | Z18: =IF(AND(ISNUMBER(X18),ISNUMBER(Y18)),(Y18-X18)*24,0) -> 5.5 | AA18: =H18+K18+N18+Q18+T18+W18+Z18 -> 27.5 | AB18: =AA18-C18 -> 2.5 | AC18: =(H18>0)+(K18>0)+(N18>0)+(Q18>0)+(T18>0)+(W18>0)+(Z18>0) -> 5 | AD18: =IF(OR(IF(ISNUMBER(G18)*ISNUMBER(I18),(I18+1-G18)*24<Parametri!$B$65),IF(ISNUMBER(J18)*ISNUMBER(L18),(L18+1-J18)*24<Parametri!$B$65),IF(ISNUMBER(M18)*ISNUMBER(O18),(O18+1-M18)*24<Parametri!$B$65),IF(ISNUMBER(P18)*ISNUMBER(R18),(R18+1-P18)*24<Parametri!$B$65),IF(ISNUMBER(S18)*ISNUMBER(U18),(U18+1-S18)*24<Parametri!$B$65),IF(ISNUMBER(V18)*ISNUMBER(X18),(X18+1-V18)*24<Parametri!$B$65),IF(ISNUMBER(Y18)*ISNUMBER(F18),(F18+1-Y18)*24<Parametri!$B$65)),"KO","OK") -> OK
A19: {=IFERROR(INDEX(Personale!$A$5:$A$40,SMALL(IF(Personale!$H$5:$H$40="",ROW(Personale!$A$5:$A$40)-ROW(Personale!$A$5)+1),15)),"")} -> DE VIDO | B19: =IFERROR(VLOOKUP($A19,Personale!$A$5:$E$40,2,0),"") -> ADDETTO | C19: =IFERROR(VLOOKUP($A19,Personale!$A$5:$E$40,3,0),0) -> 30 | D19: =IFERROR(VLOOKUP($A19,Personale!$A$5:$E$40,4,0),0) -> 5 | E19: =IFERROR(VLOOKUP($A19,Personale!$A$5:$E$40,5,0),0) -> 6 | F19: 0.58333333 | G19: 0.83333333 | H19: =IF(AND(ISNUMBER(F19),ISNUMBER(G19)),(G19-F19)*24,0) -> 6 | I19: 0.61458333 | J19: 0.88541667 | K19: =IF(AND(ISNUMBER(I19),ISNUMBER(J19)),(J19-I19)*24,0) -> 6.5 | L19: 0.35416667 | M19: 0.625 | N19: =IF(AND(ISNUMBER(L19),ISNUMBER(M19)),(M19-L19)*24,0) -> 6.5 | O19: R | P19: R | Q19: =IF(AND(ISNUMBER(O19),ISNUMBER(P19)),(P19-O19)*24,0) -> 0 | R19: 0.25 | S19: 0.52083333 | T19: =IF(AND(ISNUMBER(R19),ISNUMBER(S19)),(S19-R19)*24,0) -> 6.5 | U19: R | V19: R | W19: =IF(AND(ISNUMBER(U19),ISNUMBER(V19)),(V19-U19)*24,0) -> 0 | X19: 0.25 | Y19: 0.54166667 | Z19: =IF(AND(ISNUMBER(X19),ISNUMBER(Y19)),(Y19-X19)*24,0) -> 7 | AA19: =H19+K19+N19+Q19+T19+W19+Z19 -> 32.5 | AB19: =AA19-C19 -> 2.5 | AC19: =(H19>0)+(K19>0)+(N19>0)+(Q19>0)+(T19>0)+(W19>0)+(Z19>0) -> 5 | AD19: =IF(OR(IF(ISNUMBER(G19)*ISNUMBER(I19),(I19+1-G19)*24<Parametri!$B$65),IF(ISNUMBER(J19)*ISNUMBER(L19),(L19+1-J19)*24<Parametri!$B$65),IF(ISNUMBER(M19)*ISNUMBER(O19),(O19+1-M19)*24<Parametri!$B$65),IF(ISNUMBER(P19)*ISNUMBER(R19),(R19+1-P19)*24<Parametri!$B$65),IF(ISNUMBER(S19)*ISNUMBER(U19),(U19+1-S19)*24<Parametri!$B$65),IF(ISNUMBER(V19)*ISNUMBER(X19),(X19+1-V19)*24<Parametri!$B$65),IF(ISNUMBER(Y19)*ISNUMBER(F19),(F19+1-Y19)*24<Parametri!$B$65)),"KO","OK") -> OK
A20: {=IFERROR(INDEX(Personale!$A$5:$A$40,SMALL(IF(Personale!$H$5:$H$40="",ROW(Personale!$A$5:$A$40)-ROW(Personale!$A$5)+1),16)),"")} -> GALLINA | B20: =IFERROR(VLOOKUP($A20,Personale!$A$5:$E$40,2,0),"") -> ADDETTO | C20: =IFERROR(VLOOKUP($A20,Personale!$A$5:$E$40,3,0),0) -> 25 | D20: =IFERROR(VLOOKUP($A20,Personale!$A$5:$E$40,4,0),0) -> 5 | E20: =IFERROR(VLOOKUP($A20,Personale!$A$5:$E$40,5,0),0) -> 5 | F20: R | G20: R | H20: =IF(AND(ISNUMBER(F20),ISNUMBER(G20)),(G20-F20)*24,0) -> 0 | I20: 0.25 | J20: 0.52083333 | K20: =IF(AND(ISNUMBER(I20),ISNUMBER(J20)),(J20-I20)*24,0) -> 6.5 | L20: 0.54166667 | M20: 0.75 | N20: =IF(AND(ISNUMBER(L20),ISNUMBER(M20)),(M20-L20)*24,0) -> 5 | O20: 0.54166667 | P20: 0.79166667 | Q20: =IF(AND(ISNUMBER(O20),ISNUMBER(P20)),(P20-O20)*24,0) -> 6 | R20: 0.67708333 | S20: 0.88541667 | T20: =IF(AND(ISNUMBER(R20),ISNUMBER(S20)),(S20-R20)*24,0) -> 5 | U20: 0.66666667 | V20: 0.875 | W20: =IF(AND(ISNUMBER(U20),ISNUMBER(V20)),(V20-U20)*24,0) -> 5 | X20: R | Y20: R | Z20: =IF(AND(ISNUMBER(X20),ISNUMBER(Y20)),(Y20-X20)*24,0) -> 0 | AA20: =H20+K20+N20+Q20+T20+W20+Z20 -> 27.5 | AB20: =AA20-C20 -> 2.5 | AC20: =(H20>0)+(K20>0)+(N20>0)+(Q20>0)+(T20>0)+(W20>0)+(Z20>0) -> 5 | AD20: =IF(OR(IF(ISNUMBER(G20)*ISNUMBER(I20),(I20+1-G20)*24<Parametri!$B$65),IF(ISNUMBER(J20)*ISNUMBER(L20),(L20+1-J20)*24<Parametri!$B$65),IF(ISNUMBER(M20)*ISNUMBER(O20),(O20+1-M20)*24<Parametri!$B$65),IF(ISNUMBER(P20)*ISNUMBER(R20),(R20+1-P20)*24<Parametri!$B$65),IF(ISNUMBER(S20)*ISNUMBER(U20),(U20+1-S20)*24<Parametri!$B$65),IF(ISNUMBER(V20)*ISNUMBER(X20),(X20+1-V20)*24<Parametri!$B$65),IF(ISNUMBER(Y20)*ISNUMBER(F20),(F20+1-Y20)*24<Parametri!$B$65)),"KO","OK") -> OK
A21: {=IFERROR(INDEX(Personale!$A$5:$A$40,SMALL(IF(Personale!$H$5:$H$40="",ROW(Personale!$A$5:$A$40)-ROW(Personale!$A$5)+1),17)),"")} -> MARZANO | B21: =IFERROR(VLOOKUP($A21,Personale!$A$5:$E$40,2,0),"") -> ADDETTO | C21: =IFERROR(VLOOKUP($A21,Personale!$A$5:$E$40,3,0),0) -> 30 | D21: =IFERROR(VLOOKUP($A21,Personale!$A$5:$E$40,4,0),0) -> 5 | E21: =IFERROR(VLOOKUP($A21,Personale!$A$5:$E$40,5,0),0) -> 6 | F21: 0.33333333 | G21: 0.58333333 | H21: =IF(AND(ISNUMBER(F21),ISNUMBER(G21)),(G21-F21)*24,0) -> 6 | I21: 0.375 | J21: 0.625 | K21: =IF(AND(ISNUMBER(I21),ISNUMBER(J21)),(J21-I21)*24,0) -> 6 | L21: 0.25 | M21: 0.5 | N21: =IF(AND(ISNUMBER(L21),ISNUMBER(M21)),(M21-L21)*24,0) -> 6 | O21: 0.22916667 | P21: 0.54166667 | Q21: =IF(AND(ISNUMBER(O21),ISNUMBER(P21)),(P21-O21)*24,0) -> 7.5 | R21: R | S21: R | T21: =IF(AND(ISNUMBER(R21),ISNUMBER(S21)),(S21-R21)*24,0) -> 0 | U21: 0.375 | V21: 0.64583333 | W21: =IF(AND(ISNUMBER(U21),ISNUMBER(V21)),(V21-U21)*24,0) -> 6.5 | X21: R | Y21: R | Z21: =IF(AND(ISNUMBER(X21),ISNUMBER(Y21)),(Y21-X21)*24,0) -> 0 | AA21: =H21+K21+N21+Q21+T21+W21+Z21 -> 32 | AB21: =AA21-C21 -> 2 | AC21: =(H21>0)+(K21>0)+(N21>0)+(Q21>0)+(T21>0)+(W21>0)+(Z21>0) -> 5 | AD21: =IF(OR(IF(ISNUMBER(G21)*ISNUMBER(I21),(I21+1-G21)*24<Parametri!$B$65),IF(ISNUMBER(J21)*ISNUMBER(L21),(L21+1-J21)*24<Parametri!$B$65),IF(ISNUMBER(M21)*ISNUMBER(O21),(O21+1-M21)*24<Parametri!$B$65),IF(ISNUMBER(P21)*ISNUMBER(R21),(R21+1-P21)*24<Parametri!$B$65),IF(ISNUMBER(S21)*ISNUMBER(U21),(U21+1-S21)*24<Parametri!$B$65),IF(ISNUMBER(V21)*ISNUMBER(X21),(X21+1-V21)*24<Parametri!$B$65),IF(ISNUMBER(Y21)*ISNUMBER(F21),(F21+1-Y21)*24<Parametri!$B$65)),"KO","OK") -> OK
